Workbook

Sheet Sheet2
A3: Row Labels | B3: Count of Product Type | C3: Sum of Difference
A4: Paint | B4: 615 | C4: 11525.06
A5: Decrease | B5: 4 | C5: -12604.48
A6: Delete | B6: 14 | C6: 0
A7: Increase | B7: 331 | C7: 24129.54
A8: Same | B8: 266 | C8: 0
A9: Sundries | B9: 743 | C9: 1883.54
A10: Decrease | B10: 12 | C10: -1025.99
A11: Delete | B11: 45 | C11: 0
A12: Increase | B12: 347 | C12: 2909.53
A13: Same | B13: 339 | C13: 0
A14: Grand Total | B14: 1358 | C14: 13408.6

Sheet Akzo Sept 01 25  
A1: Enter your Item No We can't have duplicates in the system so if the cell highlights blue, you need to add ; at the end enough times to make unique Limited to 20 characters, yellow if more than this, need to cut down | B1: Enter your number (without any ; if you needed to add any in the 'No' field for duplicates) Again limited to 20 characters, need to cut down if yellow (Might be same as column A) | C1: Enter Vendor Number from Vendor List (new ERP number) | D1: Enter the suppliers name (doesn't need to be full legal one, this is just for description | E1: Paste in the suppliers description of the item | F1: Drag formula down after completing D & E Formula will combine the prior to cells We are though restricted to 50 characters so if the cell highlights in yellow it's too long, need to cut down, or move excess to description 2 column | G1: Enter if need more space to describe the Item | H1: Enter unit of measure | I1: Enter either "ITEM" or "PLANT" | J1: Enter "EXT-PLANT" or "ITEM" | K1: Enter category code to help group the items together, see "Category Code" for ones we've used so far Can add to this list though | L1: Enter Price of Item New cost 1st Jan 2024 | M1: Enter "STD20" unless you know it's not Vatable Alternatively, "REDUCED" or "ZERO" | N1: Enter a cost code for materials or plant (unless it's an overhead like stationery in which case can leave blank) | R1: 01/06/2023 Prices from 1st June | S1: Priced before 01/03/2023 | T1: Total Units Purchased 2023 | V1: Current | W1: Current Armstead -Rates on system 25th April | X1: New Deal | Y1: Old Deal | Z1: DIFF | AA1: AKZO Purchased | AB1: AKZO Price | AC1: Unit Difference | AQ1: Same | AR1: Delete | AS1: Decrease | AT1: Increase | AW1: Increase - Original Data | AX1: Increase - Updated MAT
A2: No | B2: Vendor Item No | C2: No 2 | D2: Suppliers Name | E2: Item Description | F2: Description for System | G2: Description 2 | H2: Base Unit of Measure | I2: Inventory Posting Group | J2: Gen Prod Posting Group | K2: Item Category Code | L2: Unit Cost | M2: VAT Prod Posting Group | N2: Global Dimension 2 Code | W2: Unit Cost | AL2: Inc Sundries | AM2: =COUNTIF(AP6:AP1363,"Increase")-AM3 -> 347 | AO2: New rate Sept 1 2025 | AP2: Orig | AQ2: =COUNTIF($AI:$AI,AQ1) -> 444 | AR2: =COUNTIF($AI:$AI,AR1) -> 228 | AS2: =COUNTIF($AI:$AI,AS1) -> 15 | AT2: =COUNTIF($AI:$AI,AT1) -> 671 | AU2: =SUM(AQ2:AT2) -> 1358 | AW2: =SUMIF($AP$6:$AP$1363,"Increase",AJ$6:AJ$1363) -> 948824.73 | AX2: =SUMIF($AP$6:$AP$1363,"Increase",AQ$6:AQ$1363) -> 599801.88
AL3: Inc Paint | AM3: =COUNTIFS(AL6:AL1363,"Paint",AP6:AP1363,"Increase") -> 331 | AP3: Updated | AQ3: =COUNTIF($AP:$AP,AQ1) -> 605 | AR3: =COUNTIF($AP:$AP,AR1) -> 59 | AS3: =COUNTIF($AP:$AP,AS1) -> 16 | AT3: =COUNTIF($AP:$AP,AT1) -> 678 | AU3: =SUM(AQ3:AT3) -> 1358 | AW3: =SUMIF($AP$6:$AP$1363,"Increase",AK$6:AK$1363) -> 973351.65 | AX3: =SUMIF($AP$6:$AP$1363,"Increase",AR$6:AR$1363) -> 616772.4 | AY3: =AX3-AX2 -> 16970.52 | AZ3: =AY3/AX2 -> 0.028293543
C5: DDEC01 | D5: Akzo DDC | H5: EA | I5: ITEM | J5: ITEM | K5: Paint | L5: 1.78 | M5: STD20 | N5: 3105 | S5: =SUM(R5*P5) -> 0 | T5: =SUM(R5*L5) -> 0 | AD5: PLC | AE5: Remove | AF5: May Price | AH5: Sept Price | AI5: Orig Comp | AJ5: May Val | AK5: Sept Val | AL5: Product Type | AM5: Updated PLC | AN5: Updated MAT Qty | AO5: Updated Sept Price | AP5: Updated Comp | AQ5: Updated May Val | AR5: Updated Sept Val | AS5: Difference
A6: 6188891 | B6: 6188891 | C6: DDEC01 | D6: Akzo DDC | E6: DDC Decorators Caulk White 380ML | F6: DDC Decorators Caulk White 380ML | H6: EA | I6: ITEM | J6: ITEM | K6: Paint | L6: 1.14 | M6: STD20 | N6: 3105 | R6: 1.78 | S6: 1.78 | T6: 21369 | V6: 1.14 | W6: 1.14 | X6: =SUM(V6*T6) -> 24360.66 | Y6: =SUM(L6*T6) -> 24360.66 | Z6: =SUM(X6-Y6) -> 0 | AA6: 21369 | AB6: =IFERROR(VLOOKUP(A6,'Tash Lookup'!A:E,3,FALSE),"") -> 24202 | AC6: =IFERROR(AA6-T6,"") -> 0 | AD6: Normal | AF6: 1.14 | AG6: =VLOOKUP(A6,Sheet1!$A$2:$C$1140,3,FALSE) -> 1.14 | AH6: 1.14 | AI6: =IF(ISNA(AH6),"Delete",IF(AH6=AF6,"Same",IF(AH6>AF6,"Increase","Decrease"))) -> Same | AJ6: =IFERROR(AA6*AF6,0) -> 24360.66 | AK6: =IFERROR(AA6*AH6,0) -> 24360.66 | AL6: Sundries / 3rd Party | AM6: Normal | AN6: 13797 | AO6: 1.14 | AP6: =IF(AM6="Delete","Delete",IF(AO6=AF6,"Same",IF(AO6>AF6,"Increase","Decrease"))) -> Same | AQ6: =AN6*AF6 -> 15728.58 | AR6: =AN6*AO6 -> 15728.58 | AS6: =AR6-AQ6 -> 0
A7: 6188903 | B7: 6188903 | C7: DDEC01 | D7: Akzo DDC | E7: DDC Masking Tape 48MM x 50M | F7: DDC Masking Tape 48MM x 50M | H7: EA | I7: ITEM | J7: ITEM | K7: Paint | L7: 1.22 | M7: STD20 | N7: 3105 | R7: 2.44 | S7: 2.44 | T7: 8541 | V7: 1.22 | W7: 1.22 | X7: =SUM(V7*T7) -> 10420.02 | Y7: =SUM(L7*T7) -> 10420.02 | Z7: =SUM(X7-Y7) -> 0 | AA7: 8541 | AB7: =IFERROR(VLOOKUP(A7,'Tash Lookup'!A:E,3,FALSE),"") -> 10114.89 | AC7: =IFERROR(AA7-T7,"") -> 0 | AD7: Normal | AF7: 1.22 | AG7: =VLOOKUP(A7,Sheet1!$A$2:$C$1140,3,FALSE) -> 1.24 | AH7: 1.24 | AI7: =IF(ISNA(AH7),"Delete",IF(AH7=AF7,"Same",IF(AH7>AF7,"Increase","Decrease"))) -> Increase | AJ7: =IFERROR(AA7*AF7,0) -> 10420.02 | AK7: =IFERROR(AA7*AH7,0) -> 10590.84 | AL7: Sundries / 3rd Party | AM7: Normal | AN7: 4378 | AO7: 1.24 | AP7: =IF(AM7="Delete","Delete",IF(AO7=AF7,"Same",IF(AO7>AF7,"Increase","Decrease"))) -> Increase | AQ7: =AN7*AF7 -> 5341.16 | AR7: =AN7*AO7 -> 5428.72 | AS7: =AR7-AQ7 -> 87.56
A8: 5090751 | B8: 5090751 | C8: DDEC01 | D8: Akzo DDC | E8: Dulux TR Diamond Matt Tinted Colours 5L | F8: Dulux TR Diamond Matt Tinted Colours 5L | H8: EA | I8: ITEM | J8: ITEM | K8: Paint | L8: 30.76 | M8: STD20 | N8: 3105 | R8: 31.74 | S8: 31.74 | T8: 4275 | V8: 28.1865 | W8: 30.76 | X8: =SUM(V8*T8) -> 120497.29 | Y8: =SUM(L8*T8) -> 131499 | Z8: =SUM(X8-Y8) -> -11001.713 | AA8: 4275 | AB8: =IFERROR(VLOOKUP(A8,'Tash Lookup'!A:E,3,FALSE),"") -> 131165.05 | AC8: =IFERROR(AA8-T8,"") -> 0 | AD8: Normal | AF8: 29.61 | AG8: =VLOOKUP(A8,Sheet1!$A$2:$C$1140,3,FALSE) -> 29.61 | AH8: 29.61 | AI8: =IF(ISNA(AH8),"Delete",IF(AH8=AF8,"Same",IF(AH8>AF8,"Increase","Decrease"))) -> Same | AJ8: =IFERROR(AA8*AF8,0) -> 126582.75 | AK8: =IFERROR(AA8*AH8,0) -> 126582.75 | AL8: Paint | AM8: Normal | AN8: 3449 | AO8: 29.61 | AP8: =IF(AM8="Delete","Delete",IF(AO8=AF8,"Same",IF(AO8>AF8,"Increase","Decrease"))) -> Same | AQ8: =AN8*AF8 -> 102124.89 | AR8: =AN8*AO8 -> 102124.89 | AS8: =AR8-AQ8 -> 0
A9: 5090809 | B9: 5090809 | C9: DDEC01 | D9: Akzo DDC | E9: Dulux TR Diamond Eggshell Tint Colours 5L | F9: Dulux TR Diamond Eggshell Tint Colours 5L | H9: EA | I9: ITEM | J9: ITEM | K9: Paint | L9: 35.09 | M9: STD20 | N9: 3105 | R9: 39.04 | S9: 39.04 | T9: 4196 | V9: 32.053 | W9: 35.09 | X9: =SUM(V9*T9) -> 134494.39 | Y9: =SUM(L9*T9) -> 147237.64 | Z9: =SUM(X9-Y9) -> -12743.252 | AA9: 4196 | AB9: =IFERROR(VLOOKUP(A9,'Tash Lookup'!A:E,3,FALSE),"") -> 145002.74 | AC9: =IFERROR(AA9-T9,"") -> 0 | AD9: Normal | AF9: 33.88 | AG9: =VLOOKUP(A9,Sheet1!$A$2:$C$1140,3,FALSE) -> 33.88 | AH9: 33.88 | AI9: =IF(ISNA(AH9),"Delete",IF(AH9=AF9,"Same",IF(AH9>AF9,"Increase","Decrease"))) -> Same | AJ9: =IFERROR(AA9*AF9,0) -> 142160.48 | AK9: =IFERROR(AA9*AH9,0) -> 142160.48 | AL9: Paint | AM9: Normal | AN9: 2501 | AO9: 33.88 | AP9: =IF(AM9="Delete","Delete",IF(AO9=AF9,"Same",IF(AO9>AF9,"Increase","Decrease"))) -> Same | AQ9: =AN9*AF9 -> 84733.88 | AR9: =AN9*AO9 -> 84733.88 | AS9: =AR9-AQ9 -> 0
A10: 5091663 | B10: 5091663 | C10: DDEC01 | D10: Akzo DDC | E10: DT Airsure Supermatt White 10L | F10: Dulux TR Airsure Supermatt White 10L | H10: EA | I10: ITEM | J10: ITEM | K10: Paint | L10: 30.37 | M10: STD20 | N10: 3105 | R10: 30.37 | S10: 30.37 | T10: 2692 | V10: 30.37 | W10: 30.37 | X10: =SUM(V10*T10) -> 81756.04 | Y10: =SUM(L10*T10) -> 81756.04 | Z10: =SUM(X10-Y10) -> 0 | AA10: 2692 | AB10: =IFERROR(VLOOKUP(A10,'Tash Lookup'!A:E,3,FALSE),"") -> 68395.37 | AC10: =IFERROR(AA10-T10,"") -> 0 | AD10: Normal | AF10: 29.14 | AG10: =VLOOKUP(A10,Sheet1!$A$2:$C$1140,3,FALSE) -> 29.14 | AH10: 29.14 | AI10: =IF(ISNA(AH10),"Delete",IF(AH10=AF10,"Same",IF(AH10>AF10,"Increase","Decrease"))) -> Same | AJ10: =IFERROR(AA10*AF10,0) -> 78444.88 | AK10: =IFERROR(AA10*AH10,0) -> 78444.88 | AL10: Paint | AM10: Normal | AN10: 2535 | AO10: 29.14 | AP10: =IF(AM10="Delete","Delete",IF(AO10=AF10,"Same",IF(AO10>AF10,"Increase","Decrease"))) -> Same | AQ10: =AN10*AF10 -> 73869.9 | AR10: =AN10*AO10 -> 73869.9 | AS10: =AR10-AQ10 -> 0
A11: 5293175 | B11: 5293175 | C11: DDEC01 | D11: Akzo DDC | E11: Dulux TR Supermatt White 10L (Airsure Trial Only) | F11: Dulux TR Supermatt White 10L (Airsure Trial Only) | H11: EA | I11: ITEM | J11: ITEM | K11: Paint | L11: 30.37 | M11: STD20 | N11: 3105 | R11: 30.37 | S11: 30.37 | T11: 2692 | V11: 30.37 | W11: 30.37 | X11: =SUM(V11*T11) -> 81756.04 | Y11: =SUM(L11*T11) -> 81756.04 | Z11: =SUM(X11-Y11) -> 0 | AA11: 2692 | AB11: =IFERROR(VLOOKUP(A11,'Tash Lookup'!A:E,3,FALSE),"") -> 68395.37 | AC11: =IFERROR(AA11-T11,"") -> 0 | AD11: Pre-phase-out | AF11: 30 | AG11: 30 | AH11: 30 | AI11: =IF(ISNA(AH11),"Delete",IF(AH11=AF11,"Same",IF(AH11>AF11,"Increase","Decrease"))) -> Same | AJ11: =IFERROR(AA11*AF11,0) -> 80760 | AK11: =IFERROR(AA11*AH11,0) -> 80760 | AL11: Paint | AM11: Pre-phase-out | AN11: 0 | AO11: 30 | AP11: =IF(AM11="Delete","Delete",IF(AO11=AF11,"Same",IF(AO11>AF11,"Increase","Decrease"))) -> Same | AQ11: =AN11*AF11 -> 0 | AR11: =AN11*AO11 -> 0 | AS11: =AR11-AQ11 -> 0
A12: 5218587 | B12: 5218587 | C12: DDEC01 | D12: Akzo DDC | E12: Armstead TR Contract Matt White 10L | F12: Armstead TR Contract Matt White 10L | H12: EA | I12: ITEM | J12: ITEM | K12: Paint | L12: 13.04 | M12: STD20 | N12: 3105 | R12: 15.4 | S12: 15.4 | T12: 2450 | V12: 12.388 | W12: 13.04 | X12: =SUM(V12*T12) -> 30350.6 | Y12: =SUM(L12*T12) -> 31948 | Z12: =SUM(X12-Y12) -> -1597.4 | AA12: 2450 | AB12: =IFERROR(VLOOKUP(A12,'Tash Lookup'!A:E,3,FALSE),"") -> 36831.22 | AC12: =IFERROR(AA12-T12,"") -> 0 | AD12: Normal | AF12: 12.5 | AG12: =VLOOKUP(A12,Sheet1!$A$2:$C$1140,3,FALSE) -> 12.5 | AH12: 12.5 | AI12: =IF(ISNA(AH12),"Delete",IF(AH12=AF12,"Same",IF(AH12>AF12,"Increase","Decrease"))) -> Same | AJ12: =IFERROR(AA12*AF12,0) -> 30625 | AK12: =IFERROR(AA12*AH12,0) -> 30625 | AL12: Paint | AM12: Normal | AN12: 666 | AO12: 12.5 | AP12: =IF(AM12="Delete","Delete",IF(AO12=AF12,"Same",IF(AO12>AF12,"Increase","Decrease"))) -> Same | AQ12: =AN12*AF12 -> 8325 | AR12: =AN12*AO12 -> 8325 | AS12: =AR12-AQ12 -> 0
A13: 5091671 | B13: 5091671 | C13: DDEC01 | D13: Akzo DDC | E13: Dulux TR AS Supermatt Almond White 10L | F13: Dulux TR AS Supermatt Almond White 10L | H13: EA | I13: ITEM | J13: ITEM | K13: Paint | L13: 27.84 | M13: STD20 | N13: 3105 | R13: 27.84 | S13: 27.84 | T13: 2040 | V13: 27.84 | W13: 27.84 | X13: =SUM(V13*T13) -> 56793.6 | Y13: =SUM(L13*T13) -> 56793.6 | Z13: =SUM(X13-Y13) -> 0 | AA13: 2040 | AB13: =IFERROR(VLOOKUP(A13,'Tash Lookup'!A:E,3,FALSE),"") -> 47611.45 | AC13: =IFERROR(AA13-T13,"") -> 0 | AD13: Normal | AF13: 26.7 | AG13: =VLOOKUP(A13,Sheet1!$A$2:$C$1140,3,FALSE) -> 26.7 | AH13: 26.7 | AI13: =IF(ISNA(AH13),"Delete",IF(AH13=AF13,"Same",IF(AH13>AF13,"Increase","Decrease"))) -> Same | AJ13: =IFERROR(AA13*AF13,0) -> 54468 | AK13: =IFERROR(AA13*AH13,0) -> 54468 | AL13: Paint | AM13: Normal | AN13: 1573 | AO13: 26.7 | AP13: =IF(AM13="Delete","Delete",IF(AO13=AF13,"Same",IF(AO13>AF13,"Increase","Decrease"))) -> Same | AQ13: =AN13*AF13 -> 41999.1 | AR13: =AN13*AO13 -> 41999.1 | AS13: =AR13-AQ13 -> 0
A14: 6410329 | B14: 6410329 | C14: DDEC01 | D14: Akzo DDC | E14: DT Pyroshield Eggshell Light BS Tinted 5L | F14: Dulux TR Pyroshield Eggshell Light BS Tinted 5L | H14: EA | I14: ITEM | J14: ITEM | K14: Paint | L14: 61.88 | M14: STD20 | N14: 3105 | R14: 73.35 | S14: 73.35 | T14: 1954 | V14: 61.88 | W14: 61.88 | X14: =SUM(V14*T14) -> 120913.52 | Y14: =SUM(L14*T14) -> 120913.52 | Z14: =SUM(X14-Y14) -> 0 | AA14: 1954 | AB14: =IFERROR(VLOOKUP(A14,'Tash Lookup'!A:E,3,FALSE),"") -> 121179.31 | AC14: =IFERROR(AA14-T14,"") -> 0 | AD14: Centrally stock allocated | AF14: 61.88 | AG14: =VLOOKUP(A14,Sheet1!$A$2:$C$1140,3,FALSE) -> 63.74 | AH14: 63.74 | AI14: =IF(ISNA(AH14),"Delete",IF(AH14=AF14,"Same",IF(AH14>AF14,"Increase","Decrease"))) -> Increase | AJ14: =IFERROR(AA14*AF14,0) -> 120913.52 | AK14: =IFERROR(AA14*AH14,0) -> 124547.96 | AL14: Paint | AM14: Centrally stock allocated | AN14: 718 | AO14: 63.74 | AP14: =IF(AM14="Delete","Delete",IF(AO14=AF14,"Same",IF(AO14>AF14,"Increase","Decrease"))) -> Increase | AQ14: =AN14*AF14 -> 44429.84 | AR14: =AN14*AO14 -> 45765.32 | AS14: =AR14-AQ14 -> 1335.48
A15: 5224812 | B15: 5224812 | C15: DDEC01 | D15: Akzo DDC | E15: Dulux TR Diamond Matt Tinted Colours 10L | F15: Dulux TR Diamond Matt Tinted Colours 10L | H15: EA | I15: ITEM | J15: ITEM | K15: Paint | L15: 56.91 | M15: STD20 | N15: 3105 | R15: 60.3 | S15: 60.3 | T15: 1922 | V15: 51.984 | W15: 56.91 | X15: =SUM(V15*T15) -> 99913.248 | Y15: =SUM(L15*T15) -> 109381.02 | Z15: =SUM(X15-Y15) -> -9467.772 | AA15: 1922 | AB15: =IFERROR(VLOOKUP(A15,'Tash Lookup'!A:E,3,FALSE),"") -> 110788.03 | AC15: =IFERROR(AA15-T15,"") -> 0 | AD15: Normal | AF15: 54.63 | AG15: =VLOOKUP(A15,Sheet1!$A$2:$C$1140,3,FALSE) -> 54.63 | AH15: 54.63 | AI15: =IF(ISNA(AH15),"Delete",IF(AH15=AF15,"Same",IF(AH15>AF15,"Increase","Decrease"))) -> Same | AJ15: =IFERROR(AA15*AF15,0) -> 104998.86 | AK15: =IFERROR(AA15*AH15,0) -> 104998.86 | AL15: Paint | AM15: Normal | AN15: 309 | AO15: 54.63 | AP15: =IF(AM15="Delete","Delete",IF(AO15=AF15,"Same",IF(AO15>AF15,"Increase","Decrease"))) -> Same | AQ15: =AN15*AF15 -> 16880.67 | AR15: =AN15*AO15 -> 16880.67 | AS15: =AR15-AQ15 -> 0
A16: 5090805 | B16: 5090805 | C16: DDEC01 | D16: Akzo DDC | E16: Dulux TR W/S Msnry Tinted Colours 5L | F16: Dulux TR W/S Msnry Tinted Colours 5L | H16: EA | I16: ITEM | J16: ITEM | K16: Paint | L16: 28.69 | M16: STD20 | N16: 3105 | R16: 28.69 | S16: 28.69 | T16: 1867 | V16: 28.69 | W16: 28.69 | X16: =SUM(V16*T16) -> 53564.23 | Y16: =SUM(L16*T16) -> 53564.23 | Z16: =SUM(X16-Y16) -> 0 | AA16: 1867 | AB16: =IFERROR(VLOOKUP(A16,'Tash Lookup'!A:E,3,FALSE),"") -> 53559.5 | AC16: =IFERROR(AA16-T16,"") -> 0 | AD16: Normal | AF16: 29.82 | AG16: =VLOOKUP(A16,Sheet1!$A$2:$C$1140,3,FALSE) -> 29.82 | AH16: 29.82 | AI16: =IF(ISNA(AH16),"Delete",IF(AH16=AF16,"Same",IF(AH16>AF16,"Increase","Decrease"))) -> Same | AJ16: =IFERROR(AA16*AF16,0) -> 55673.94 | AK16: =IFERROR(AA16*AH16,0) -> 55673.94 | AL16: Paint | AM16: Normal | AN16: 1869 | AO16: 29.82 | AP16: =IF(AM16="Delete","Delete",IF(AO16=AF16,"Same",IF(AO16>AF16,"Increase","Decrease"))) -> Same | AQ16: =AN16*AF16 -> 55733.58 | AR16: =AN16*AO16 -> 55733.58 | AS16: =AR16-AQ16 -> 0
A17: 5583720 | B17: 5583720 | C17: DDEC01 | D17: Akzo DDC | E17: Dulux TR W/S Msnry Smooth Magnolia 7.5L | F17: Dulux TR W/S Msnry Smooth Magnolia 7.5L | H17: EA | I17: ITEM | J17: ITEM | K17: Paint | L17: 25.99 | M17: STD20 | N17: 3105 | R17: 25.99 | S17: 25.99 | T17: 1865 | V17: 17.46 | W17: 25.99 | X17: =SUM(V17*T17) -> 32562.9 | Y17: =SUM(L17*T17) -> 48471.35 | Z17: =SUM(X17-Y17) -> -15908.45 | AA17: 1865 | AB17: =IFERROR(VLOOKUP(A17,'Tash Lookup'!A:E,3,FALSE),"") -> 48032.35 | AC17: =IFERROR(AA17-T17,"") -> 0 | AD17: Active Promo / Seasonal | AF17: 17.54 | AG17: =VLOOKUP(A17,Sheet1!$A$2:$C$1140,3,FALSE) -> 17.46 | AH17: 17.46 | AI17: =IF(ISNA(AH17),"Delete",IF(AH17=AF17,"Same",IF(AH17>AF17,"Increase","Decrease"))) -> Decrease | AJ17: =IFERROR(AA17*AF17,0) -> 32712.1 | AK17: =IFERROR(AA17*AH17,0) -> 32562.9 | AL17: Sundries / 3rd Party | AM17: Active Promo / Seasonal | AN17: 1927 | AO17: 17.46 | AP17: =IF(AM17="Delete","Delete",IF(AO17=AF17,"Same",IF(AO17>AF17,"Increase","Decrease"))) -> Decrease | AQ17: =AN17*AF17 -> 33799.58 | AR17: =AN17*AO17 -> 33645.42 | AS17: =AR17-AQ17 -> -154.16
A18: 5090801 | B18: 5090801 | C18: DDEC01 | D18: Akzo DDC | E18: Dulux TR V/Matt Tinted Colours 5L | F18: Dulux TR V/Matt Tinted Colours 5L | H18: EA | I18: ITEM | J18: ITEM | K18: Paint | L18: 25.73 | M18: STD20 | N18: 3105 | R18: 29.43 | S18: 29.43 | T18: 1758 | V18: 23.5125 | W18: 25.73 | X18: =SUM(V18*T18) -> 41334.975 | Y18: =SUM(L18*T18) -> 45233.34 | Z18: =SUM(X18-Y18) -> -3898.365 | AA18: 1758 | AB18: =IFERROR(VLOOKUP(A18,'Tash Lookup'!A:E,3,FALSE),"") -> 45451.42 | AC18: =IFERROR(AA18-T18,"") -> 0 | AD18: Normal | AF18: 24.55 | AG18: =VLOOKUP(A18,Sheet1!$A$2:$C$1140,3,FALSE) -> 24.55 | AH18: 24.55 | AI18: =IF(ISNA(AH18),"Delete",IF(AH18=AF18,"Same",IF(AH18>AF18,"Increase","Decrease"))) -> Same | AJ18: =IFERROR(AA18*AF18,0) -> 43158.9 | AK18: =IFERROR(AA18*AH18,0) -> 43158.9 | AL18: Paint | AM18: Normal | AN18: 1461 | AO18: 24.55 | AP18: =IF(AM18="Delete","Delete",IF(AO18=AF18,"Same",IF(AO18>AF18,"Increase","Decrease"))) -> Same | AQ18: =AN18*AF18 -> 35867.55 | AR18: =AN18*AO18 -> 35867.55 | AS18: =AR18-AQ18 -> 0
A19: 6188899 | B19: 6188899 | C19: DDEC01 | D19: Akzo DDC | E19: DDC Flexible Finishing Pad Medium/Coarse | F19: DDC Flexible Finishing Pad Medium/Coarse | H19: EA | I19: ITEM | J19: ITEM | K19: Paint | L19: 0.78 | M19: STD20 | N19: 3105 | R19: 0.78 | S19: 0.78 | T19: 1700 | V19: 0.78 | W19: 0.78 | X19: =SUM(V19*T19) -> 1326 | Y19: =SUM(L19*T19) -> 1326 | Z19: =SUM(X19-Y19) -> 0 | AA19: 1700 | AB19: =IFERROR(VLOOKUP(A19,'Tash Lookup'!A:E,3,FALSE),"") -> 1322.69 | AC19: =IFERROR(AA19-T19,"") -> 0 | AD19: Normal | AF19: 0.78 | AG19: =VLOOKUP(A19,Sheet1!$A$2:$C$1140,3,FALSE) -> 0.79 | AH19: 0.79 | AI19: =IF(ISNA(AH19),"Delete",IF(AH19=AF19,"Same",IF(AH19>AF19,"Increase","Decrease"))) -> Increase | AJ19: =IFERROR(AA19*AF19,0) -> 1326 | AK19: =IFERROR(AA19*AH19,0) -> 1343 | AL19: Sundries / 3rd Party | AM19: Normal | AN19: 1529 | AO19: 0.79 | AP19: =IF(AM19="Delete","Delete",IF(AO19=AF19,"Same",IF(AO19>AF19,"Increase","Decrease"))) -> Increase | AQ19: =AN19*AF19 -> 1192.62 | AR19: =AN19*AO19 -> 1207.91 | AS19: =AR19-AQ19 -> 15.29
A20: 5082320 | B20: 5082320 | C20: DDEC01 | D20: Akzo DDC | E20: Dulux TR Diamond Eggshell PBW 5L | F20: Dulux TR Diamond Eggshell PBW 5L | H20: EA | I20: ITEM | J20: ITEM | K20: Paint | L20: 31.79 | M20: STD20 | N20: 3105 | R20: 31.79 | S20: 31.79 | T20: 1590 | V20: 26.106 | W20: 31.79 | X20: =SUM(V20*T20) -> 41508.54 | Y20: =SUM(L20*T20) -> 50546.1 | Z20: =SUM(X20-Y20) -> -9037.56 | AA20: 1590 | AB20: =IFERROR(VLOOKUP(A20,'Tash Lookup'!A:E,3,FALSE),"") -> 49689.25 | AC20: =IFERROR(AA20-T20,"") -> 0 | AD20: Normal | AF20: 25.5 | AG20: =VLOOKUP(A20,Sheet1!$A$2:$C$1140,3,FALSE) -> 25.5 | AH20: 25.5 | AI20: =IF(ISNA(AH20),"Delete",IF(AH20=AF20,"Same",IF(AH20>AF20,"Increase","Decrease"))) -> Same | AJ20: =IFERROR(AA20*AF20,0) -> 40545 | AK20: =IFERROR(AA20*AH20,0) -> 40545 | AL20: Paint | AM20: Normal | AN20: 1701 | AO20: 25.5 | AP20: =IF(AM20="Delete","Delete",IF(AO20=AF20,"Same",IF(AO20>AF20,"Increase","Decrease"))) -> Same | AQ20: =AN20*AF20 -> 43375.5 | AR20: =AN20*AO20 -> 43375.5 | AS20: =AR20-AQ20 -> 0
A21: 5091649 | B21: 5091649 | C21: DDEC01 | D21: Akzo DDC | E21: Dulux TR V/Matt White 10L | F21: Dulux TR V/Matt White 10L | H21: EA | I21: ITEM | J21: ITEM | K21: Paint | L21: 33.56 | M21: STD20 | N21: 3105 | R21: 33.01 | S21: 33.01 | T21: 1410 | V21: 30.6565 | W21: 33.56 | X21: =SUM(V21*T21) -> 43225.665 | Y21: =SUM(L21*T21) -> 47319.6 | Z21: =SUM(X21-Y21) -> -4093.935 | AA21: 1410 | AB21: =IFERROR(VLOOKUP(A21,'Tash Lookup'!A:E,3,FALSE),"") -> 46714.51 | AC21: =IFERROR(AA21-T21,"") -> 0 | AD21: Normal | AF21: 30.61 | AG21: =VLOOKUP(A21,Sheet1!$A$2:$C$1140,3,FALSE) -> 30.61 | AH21: 30.61 | AI21: =IF(ISNA(AH21),"Delete",IF(AH21=AF21,"Same",IF(AH21>AF21,"Increase","Decrease"))) -> Same | AJ21: =IFERROR(AA21*AF21,0) -> 43160.1 | AK21: =IFERROR(AA21*AH21,0) -> 43160.1 | AL21: Paint | AM21: Normal | AN21: 1065 | AO21: 30.61 | AP21: =IF(AM21="Delete","Delete",IF(AO21=AF21,"Same",IF(AO21>AF21,"Increase","Decrease"))) -> Same | AQ21: =AN21*AF21 -> 32599.65 | AR21: =AN21*AO21 -> 32599.65 | AS21: =AR21-AQ21 -> 0
A22: 5583723 | B22: 5583723 | C22: DDEC01 | D22: Akzo DDC | E22: Dulux TR W/S Msnry Smooth PBW 7.5L | F22: Dulux TR W/S Msnry Smooth PBW 7.5L | H22: EA | I22: ITEM | J22: ITEM | K22: Paint | L22: 25.99 | M22: STD20 | N22: 3105 | R22: 25.99 | S22: 25.99 | T22: 1330 | V22: 17.46 | W22: 25.99 | X22: =SUM(V22*T22) -> 23221.8 | Y22: =SUM(L22*T22) -> 34566.7 | Z22: =SUM(X22-Y22) -> -11344.9 | AA22: 1330 | AB22: =IFERROR(VLOOKUP(A22,'Tash Lookup'!A:E,3,FALSE),"") -> 34298.7 | AC22: =IFERROR(AA22-T22,"") -> 0 | AD22: Active Promo / Seasonal | AF22: 17.64 | AG22: =VLOOKUP(A22,Sheet1!$A$2:$C$1140,3,FALSE) -> 17.46 | AH22: 17.46 | AI22: =IF(ISNA(AH22),"Delete",IF(AH22=AF22,"Same",IF(AH22>AF22,"Increase","Decrease"))) -> Decrease | AJ22: =IFERROR(AA22*AF22,0) -> 23461.2 | AK22: =IFERROR(AA22*AH22,0) -> 23221.8 | AL22: Sundries / 3rd Party | AM22: Active Promo / Seasonal | AN22: 1551 | AO22: 17.46 | AP22: =IF(AM22="Delete","Delete",IF(AO22=AF22,"Same",IF(AO22>AF22,"Increase","Decrease"))) -> Decrease | AQ22: =AN22*AF22 -> 27359.64 | AR22: =AN22*AO22 -> 27080.46 | AS22: =AR22-AQ22 -> -279.18
A23: 5110680 | B23: 5110680 | C23: DDEC01 | D23: Akzo DDC | E23: Dulux TR W/S Ult Opq Tint Colours 5L | F23: Dulux TR W/S Ult Opq Tint Colours 5L | H23: EA | I23: ITEM | J23: ITEM | K23: Paint | L23: 50.94 | M23: STD20 | N23: 3105 | R23: 67.84 | S23: 67.84 | T23: 1268 | V23: 55.5 | W23: 50.94 | X23: =SUM(V23*T23) -> 70374 | Y23: =SUM(L23*T23) -> 64591.92 | Z23: =SUM(X23-Y23) -> 5782.08 | AA23: 1268 | AB23: =IFERROR(VLOOKUP(A23,'Tash Lookup'!A:E,3,FALSE),"") -> 65856.05 | AC23: =IFERROR(AA23-T23,"") -> 0 | AD23: Normal | AF23: 55.74 | AG23: =VLOOKUP(A23,Sheet1!$A$2:$C$1140,3,FALSE) -> 57.41 | AH23: 57.41 | AI23: =IF(ISNA(AH23),"Delete",IF(AH23=AF23,"Same",IF(AH23>AF23,"Increase","Decrease"))) -> Increase | AJ23: =IFERROR(AA23*AF23,0) -> 70678.32 | AK23: =IFERROR(AA23*AH23,0) -> 72795.88 | AL23: Paint | AM23: Normal | AN23: 706 | AO23: 57.41 | AP23: =IF(AM23="Delete","Delete",IF(AO23=AF23,"Same",IF(AO23>AF23,"Increase","Decrease"))) -> Increase | AQ23: =AN23*AF23 -> 39352.44 | AR23: =AN23*AO23 -> 40531.46 | AS23: =AR23-AQ23 -> 1179.02
... A40: 6183864 | B40: 6183864 | C40: DDEC01 | D40: Akzo DDC | E40: DDC Long Pile Woven Sleeve 9IN | F40: DDC Long Pile Woven Sleeve 9IN | H40: EA | I40: ITEM | J40: ITEM | K40: Paint | L40: 1.61 | M40: STD20 | N40: 3105 | R40: 5.8 | S40: 5.8 | T40: 774 | V40: 5.8 | W40: 1.61 | X40: =SUM(V40*T40) -> 4489.2 | Y40: =SUM(L40*T40) -> 1246.14 | Z40: =SUM(X40-Y40) -> 3243.06 | AA40: 774 | AB40: =IFERROR(VLOOKUP(A40,'Tash Lookup'!A:E,3,FALSE),"") -> 1238.08 | AC40: =IFERROR(AA40-T40,"") -> 0 | AD40: Normal | AF40: 1.41 | AG40: =VLOOKUP(A40,Sheet1!$A$2:$C$1140,3,FALSE) -> 1.44 | AH40: 1.44 | AI40: =IF(ISNA(AH40),"Delete",IF(AH40=AF40,"Same",IF(AH40>AF40,"Increase","Decrease"))) -> Increase | AJ40: =IFERROR(AA40*AF40,0) -> 1091.34 | AK40: =IFERROR(AA40*AH40,0) -> 1114.56 | AL40: Sundries / 3rd Party | AM40: Normal | AN40: 1174 | AO40: 1.44 | AP40: =IF(AM40="Delete","Delete",IF(AO40=AF40,"Same",IF(AO40>AF40,"Increase","Decrease"))) -> Increase | AQ40: =AN40*AF40 -> 1655.34 | AR40: =AN40*AO40 -> 1690.56 | AS40: =AR40-AQ40 -> 35.22
A41: 5180498 | B41: 5180498 | C41: DDEC01 | D41: Akzo DDC | E41: Cuprinol Cladding & Fence Opq Rustic Walnut 10L | F41: Cuprinol Cladding & Fence Opq Rustic Walnut 10L | H41: EA | I41: ITEM | J41: ITEM | K41: Paint | L41: 35.4 | M41: STD20 | N41: 3105 | R41: 35.4 | S41: 35.4 | T41: 765 | V41: 35.4 | W41: 35.4 | X41: =SUM(V41*T41) -> 27081 | Y41: =SUM(L41*T41) -> 27081 | Z41: =SUM(X41-Y41) -> 0 | AA41: 765 | AB41: =IFERROR(VLOOKUP(A41,'Tash Lookup'!A:E,3,FALSE),"") -> 27087.18 | AC41: =IFERROR(AA41-T41,"") -> 0 | AD41: Pre-phase-out | AF41: 37.22 | AG41: =VLOOKUP(A41,Sheet1!$A$2:$C$1140,3,FALSE) -> #N/A | AH41: #N/A | AI41: =IF(ISNA(AH41),"Delete",IF(AH41=AF41,"Same",IF(AH41>AF41,"Increase","Decrease"))) -> Delete | AJ41: =IFERROR(AA41*AF41,0) -> 28473.3 | AK41: =IFERROR(AA41*AH41,0) -> 0 | AL41: Paint | AM41: Phase-out | AN41: 0 | AO41: 37.22 | AP41: =IF(AM41="Delete","Delete",IF(AO41=AF41,"Same",IF(AO41>AF41,"Increase","Decrease"))) -> Same | AQ41: =AN41*AF41 -> 0 | AR41: =AN41*AO41 -> 0 | AS41: =AR41-AQ41 -> 0
A42: 5092359 | B42: 5092359 | C42: DDEC01 | D42: Akzo DDC | E42: Dulux TR Diamond Eggshell Mag 5L | F42: Dulux TR Diamond Eggshell Mag 5L | H42: EA | I42: ITEM | J42: ITEM | K42: Paint | L42: 24.44 | M42: STD20 | N42: 3105 | R42: 24.44 | S42: 24.44 | T42: 729 | V42: 22.059 | W42: 24.44 | X42: =SUM(V42*T42) -> 16081.011 | Y42: =SUM(L42*T42) -> 17816.76 | Z42: =SUM(X42-Y42) -> -1735.749 | AA42: 729 | AB42: =IFERROR(VLOOKUP(A42,'Tash Lookup'!A:E,3,FALSE),"") -> 17637.53 | AC42: =IFERROR(AA42-T42,"") -> 0 | AD42: Normal | AF42: 24.52 | AG42: =VLOOKUP(A42,Sheet1!$A$2:$C$1140,3,FALSE) -> 24.52 | AH42: 24.52 | AI42: =IF(ISNA(AH42),"Delete",IF(AH42=AF42,"Same",IF(AH42>AF42,"Increase","Decrease"))) -> Same | AJ42: =IFERROR(AA42*AF42,0) -> 17875.08 | AK42: =IFERROR(AA42*AH42,0) -> 17875.08 | AL42: Paint | AM42: Normal | AN42: 433 | AO42: 24.52 | AP42: =IF(AM42="Delete","Delete",IF(AO42=AF42,"Same",IF(AO42>AF42,"Increase","Decrease"))) -> Same | AQ42: =AN42*AF42 -> 10617.16 | AR42: =AN42*AO42 -> 10617.16 | AS42: =AR42-AQ42 -> 0
A43: 5218683 | B43: 5218683 | C43: DDEC01 | D43: Akzo DDC | E43: Armstead TR V/Matt White 10L | F43: Armstead TR V/Matt White 10L | H43: EA | I43: ITEM | J43: ITEM | K43: Paint | L43: 20.05 | M43: STD20 | N43: 3105 | R43: 24.5 | S43: 24.5 | T43: 718 | V43: 20.05 | W43: 14.99 | X43: =SUM(V43*T43) -> 14395.9 | Y43: =SUM(L43*T43) -> 14395.9 | Z43: =SUM(X43-Y43) -> 0 | AA43: 718 | AB43: =IFERROR(VLOOKUP(A43,'Tash Lookup'!A:E,3,FALSE),"") -> 12437.27 | AC43: =IFERROR(AA43-T43,"") -> 0 | AD43: Normal | AF43: 19.32 | AG43: =VLOOKUP(A43,Sheet1!$A$2:$C$1140,3,FALSE) -> 19.32 | AH43: 19.32 | AI43: =IF(ISNA(AH43),"Delete",IF(AH43=AF43,"Same",IF(AH43>AF43,"Increase","Decrease"))) -> Same | AJ43: =IFERROR(AA43*AF43,0) -> 13871.76 | AK43: =IFERROR(AA43*AH43,0) -> 13871.76 | AL43: Paint | AM43: Normal | AN43: 189 | AO43: 19.32 | AP43: =IF(AM43="Delete","Delete",IF(AO43=AF43,"Same",IF(AO43>AF43,"Increase","Decrease"))) -> Same | AQ43: =AN43*AF43 -> 3651.48 | AR43: =AN43*AO43 -> 3651.48 | AS43: =AR43-AQ43 -> 0
A44: 5090796 | B44: 5090796 | C44: DDEC01 | D44: Akzo DDC | E44: Dulux TR Supermatt Tint Colours 10L | F44: Dulux TR Supermatt Tint Colours 10L | H44: EA | I44: ITEM | J44: ITEM | K44: Paint | L44: 35.84 | M44: STD20 | N44: 3105 | R44: 35.84 | S44: 35.84 | T44: 709 | V44: 35.84 | W44: 35.84 | X44: =SUM(V44*T44) -> 25410.56 | Y44: =SUM(L44*T44) -> 25410.56 | Z44: =SUM(X44-Y44) -> 0 | AA44: 709 | AB44: =IFERROR(VLOOKUP(A44,'Tash Lookup'!A:E,3,FALSE),"") -> 25361.15 | AC44: =IFERROR(AA44-T44,"") -> 0 | AD44: Normal | AF44: 40.03 | AG44: =VLOOKUP(A44,Sheet1!$A$2:$C$1140,3,FALSE) -> 40.03 | AH44: 40.03 | AI44: =IF(ISNA(AH44),"Delete",IF(AH44=AF44,"Same",IF(AH44>AF44,"Increase","Decrease"))) -> Same | AJ44: =IFERROR(AA44*AF44,0) -> 28381.27 | AK44: =IFERROR(AA44*AH44,0) -> 28381.27 | AL44: Paint | AM44: Normal | AN44: 447 | AO44: 40.03 | AP44: =IF(AM44="Delete","Delete",IF(AO44=AF44,"Same",IF(AO44>AF44,"Increase","Decrease"))) -> Same | AQ44: =AN44*AF44 -> 17893.41 | AR44: =AN44*AO44 -> 17893.41 | AS44: =AR44-AQ44 -> 0
A45: 5219317 | B45: 5219317 | C45: DDEC01 | D45: Akzo DDC | E45: Armstead TR Floor Paint Tinted Colours 5L | F45: Armstead TR Floor Paint Tinted Colours 5L | H45: EA | I45: ITEM | J45: ITEM | K45: Paint | L45: 24.6 | M45: STD20 | N45: 3105 | R45: 24.6 | S45: 24.6 | T45: 697 | V45: 24.6 | W45: 21.94 | X45: =SUM(V45*T45) -> 17146.2 | Y45: =SUM(L45*T45) -> 17146.2 | Z45: =SUM(X45-Y45) -> 0 | AA45: 697 | AB45: =IFERROR(VLOOKUP(A45,'Tash Lookup'!A:E,3,FALSE),"") -> 16646.21 | AC45: =IFERROR(AA45-T45,"") -> 0 | AD45: Normal | AF45: 26.86 | AG45: =VLOOKUP(A45,Sheet1!$A$2:$C$1140,3,FALSE) -> 27.67 | AH45: 27.67 | AI45: =IF(ISNA(AH45),"Delete",IF(AH45=AF45,"Same",IF(AH45>AF45,"Increase","Decrease"))) -> Increase | AJ45: =IFERROR(AA45*AF45,0) -> 18721.42 | AK45: =IFERROR(AA45*AH45,0) -> 19285.99 | AL45: Paint | AM45: Normal | AN45: 65 | AO45: 27.67 | AP45: =IF(AM45="Delete","Delete",IF(AO45=AF45,"Same",IF(AO45>AF45,"Increase","Decrease"))) -> Increase | AQ45: =AN45*AF45 -> 1745.9 | AR45: =AN45*AO45 -> 1798.55 | AS45: =AR45-AQ45 -> 52.65
A46: 5180448 | B46: 5180448 | C46: DDEC01 | D46: Akzo DDC | E46: Dulux TR W/S Ext Gloss PBW 5L | F46: Dulux TR W/S Ext Gloss PBW 5L | H46: EA | I46: ITEM | J46: ITEM | K46: Paint | L46: 35.16 | M46: STD20 | N46: 3105 | R46: 35.16 | S46: 35.16 | T46: 696 | V46: 35.16 | W46: 35.16 | X46: =SUM(V46*T46) -> 24471.36 | Y46: =SUM(L46*T46) -> 24471.36 | Z46: =SUM(X46-Y46) -> 0 | AA46: 696 | AB46: =IFERROR(VLOOKUP(A46,'Tash Lookup'!A:E,3,FALSE),"") -> 24301.93 | AC46: =IFERROR(AA46-T46,"") -> 0 | AD46: Normal | AF46: 36.44 | AG46: =VLOOKUP(A46,Sheet1!$A$2:$C$1140,3,FALSE) -> 36.44 | AH46: 36.44 | AI46: =IF(ISNA(AH46),"Delete",IF(AH46=AF46,"Same",IF(AH46>AF46,"Increase","Decrease"))) -> Same | AJ46: =IFERROR(AA46*AF46,0) -> 25362.24 | AK46: =IFERROR(AA46*AH46,0) -> 25362.24 | AL46: Paint | AM46: Normal | AN46: 563 | AO46: 36.44 | AP46: =IF(AM46="Delete","Delete",IF(AO46=AF46,"Same",IF(AO46>AF46,"Increase","Decrease"))) -> Same | AQ46: =AN46*AF46 -> 20515.72 | AR46: =AN46*AO46 -> 20515.72 | AS46: =AR46-AQ46 -> 0
A47: 5097226 | B47: 5097226 | C47: DDEC01 | D47: Akzo DDC | E47: Dulux TR M/Shield Satin Tinted Colours 5L | F47: Dulux TR M/Shield Satin Tinted Colours 5L | H47: EA | I47: ITEM | J47: ITEM | K47: Paint | L47: 63.18 | M47: STD20 | N47: 3105 | R47: 63.18 | S47: 63.18 | T47: 692 | V47: 63.18 | W47: 63.18 | X47: =SUM(V47*T47) -> 43720.56 | Y47: =SUM(L47*T47) -> 43720.56 | Z47: =SUM(X47-Y47) -> 0 | AA47: 692 | AB47: =IFERROR(VLOOKUP(A47,'Tash Lookup'!A:E,3,FALSE),"") -> 43014.02 | AC47: =IFERROR(AA47-T47,"") -> 0 | AD47: Normal | AF47: 66.78 | AG47: =VLOOKUP(A47,Sheet1!$A$2:$C$1140,3,FALSE) -> 68.78 | AH47: 68.78 | AI47: =IF(ISNA(AH47),"Delete",IF(AH47=AF47,"Same",IF(AH47>AF47,"Increase","Decrease"))) -> Increase | AJ47: =IFERROR(AA47*AF47,0) -> 46211.76 | AK47: =IFERROR(AA47*AH47,0) -> 47595.76 | AL47: Paint | AM47: Normal | AN47: 43 | AO47: 68.78 | AP47: =IF(AM47="Delete","Delete",IF(AO47=AF47,"Same",IF(AO47>AF47,"Increase","Decrease"))) -> Increase | AQ47: =AN47*AF47 -> 2871.54 | AR47: =AN47*AO47 -> 2957.54 | AS47: =AR47-AQ47 -> 86
A48: 6188902 | B48: 6188902 | C48: DDEC01 | D48: Akzo DDC | E48: DDC Masking Tape 36MM x 50M | F48: DDC Masking Tape 36MM x 50M | H48: EA | I48: ITEM | J48: ITEM | K48: Paint | L48: 1.93 | M48: STD20 | N48: 3105 | R48: 1.93 | S48: 1.93 | T48: 613 | V48: 1.93 | W48: 1.93 | X48: =SUM(V48*T48) -> 1183.09 | Y48: =SUM(L48*T48) -> 1183.09 | Z48: =SUM(X48-Y48) -> 0 | AA48: 613 | AB48: =IFERROR(VLOOKUP(A48,'Tash Lookup'!A:E,3,FALSE),"") -> 1159.26 | AC48: =IFERROR(AA48-T48,"") -> 0 | AD48: Normal | AF48: 1.93 | AG48: =VLOOKUP(A48,Sheet1!$A$2:$C$1140,3,FALSE) -> 1.97 | AH48: 1.97 | AI48: =IF(ISNA(AH48),"Delete",IF(AH48=AF48,"Same",IF(AH48>AF48,"Increase","Decrease"))) -> Increase | AJ48: =IFERROR(AA48*AF48,0) -> 1183.09 | AK48: =IFERROR(AA48*AH48,0) -> 1207.61 | AL48: Sundries / 3rd Party | AM48: Normal | AN48: 226 | AO48: 1.97 | AP48: =IF(AM48="Delete","Delete",IF(AO48=AF48,"Same",IF(AO48>AF48,"Increase","Decrease"))) -> Increase | AQ48: =AN48*AF48 -> 436.18 | AR48: =AN48*AO48 -> 445.22 | AS48: =AR48-AQ48 -> 9.04
A49: 6188900 | B49: 6188900 | C49: DDEC01 | D49: Akzo DDC | E49: DDC Flexible Finishing Pad Extra Fine/Fine | F49: DDC Flexible Finishing Pad Extra Fine/Fine | H49: EA | I49: ITEM | J49: ITEM | K49: Paint | L49: 0.78 | M49: STD20 | N49: 3105 | R49: 0.78 | S49: 0.78 | T49: 610 | V49: 0.78 | W49: 0.78 | X49: =SUM(V49*T49) -> 475.8 | Y49: =SUM(L49*T49) -> 475.8 | Z49: =SUM(X49-Y49) -> 0 | AA49: 610 | AB49: =IFERROR(VLOOKUP(A49,'Tash Lookup'!A:E,3,FALSE),"") -> 476.25 | AC49: =IFERROR(AA49-T49,"") -> 0 | AD49: Normal | AF49: 0.78 | AG49: =VLOOKUP(A49,Sheet1!$A$2:$C$1140,3,FALSE) -> 0.79 | AH49: 0.79 | AI49: =IF(ISNA(AH49),"Delete",IF(AH49=AF49,"Same",IF(AH49>AF49,"Increase","Decrease"))) -> Increase | AJ49: =IFERROR(AA49*AF49,0) -> 475.8 | AK49: =IFERROR(AA49*AH49,0) -> 481.9 | AL49: Sundries / 3rd Party | AM49: Normal | AN49: 856 | AO49: 0.79 | AP49: =IF(AM49="Delete","Delete",IF(AO49=AF49,"Same",IF(AO49>AF49,"Increase","Decrease"))) -> Increase | AQ49: =AN49*AF49 -> 667.68 | AR49: =AN49*AO49 -> 676.24 | AS49: =AR49-AQ49 -> 8.56
A50: 5556023 | B50: 5556023 | C50: DDEC01 | D50: Akzo DDC | E50: DT Pyroshield Matt White 5L | F50: Dulux TR Pyroshield Matt White 5L | H50: EA | I50: ITEM | J50: ITEM | K50: Paint | L50: 52.61 | M50: STD20 | N50: 3105 | R50: 52.61 | S50: 52.61 | T50: 605 | V50: 52.61 | W50: 52.61 | X50: =SUM(V50*T50) -> 31829.05 | Y50: =SUM(L50*T50) -> 31829.05 | Z50: =SUM(X50-Y50) -> 0 | AA50: 605 | AB50: =IFERROR(VLOOKUP(A50,'Tash Lookup'!A:E,3,FALSE),"") -> 30537.97 | AC50: =IFERROR(AA50-T50,"") -> 0 | AD50: Centrally stock allocated | AF50: 44.99 | AG50: =VLOOKUP(A50,Sheet1!$A$2:$C$1140,3,FALSE) -> 44.99 | AH50: 44.99 | AI50: =IF(ISNA(AH50),"Delete",IF(AH50=AF50,"Same",IF(AH50>AF50,"Increase","Decrease"))) -> Same | AJ50: =IFERROR(AA50*AF50,0) -> 27218.95 | AK50: =IFERROR(AA50*AH50,0) -> 27218.95 | AL50: Paint | AM50: Centrally stock allocated | AN50: 314 | AO50: 44.99 | AP50: =IF(AM50="Delete","Delete",IF(AO50=AF50,"Same",IF(AO50>AF50,"Increase","Decrease"))) -> Same | AQ50: =AN50*AF50 -> 14126.86 | AR50: =AN50*AO50 -> 14126.86 | AS50: =AR50-AQ50 -> 0
A51: 5196657 | B51: 5196657 | C51: DDEC01 | D51: Akzo DDC | E51: Dulux TR Drywall Primer Sealer 10L | F51: Dulux TR Drywall Primer Sealer 10L | H51: EA | I51: ITEM | J51: ITEM | K51: Paint | L51: 34.41 | M51: STD20 | N51: 3105 | R51: 34.41 | S51: 34.41 | T51: 604 | V51: 34.41 | W51: 34.41 | X51: =SUM(V51*T51) -> 20783.64 | Y51: =SUM(L51*T51) -> 20783.64 | Z51: =SUM(X51-Y51) -> 0 | AA51: 604 | AB51: =IFERROR(VLOOKUP(A51,'Tash Lookup'!A:E,3,FALSE),"") -> 20740.35 | AC51: =IFERROR(AA51-T51,"") -> 0 | AD51: Centrally stock allocated | AF51: 35.34 | AG51: =VLOOKUP(A51,Sheet1!$A$2:$C$1140,3,FALSE) -> 35.34 | AH51: 35.34 | AI51: =IF(ISNA(AH51),"Delete",IF(AH51=AF51,"Same",IF(AH51>AF51,"Increase","Decrease"))) -> Same | AJ51: =IFERROR(AA51*AF51,0) -> 21345.36 | AK51: =IFERROR(AA51*AH51,0) -> 21345.36 | AL51: Paint | AM51: Normal | AN51: 10 | AO51: 35.34 | AP51: =IF(AM51="Delete","Delete",IF(AO51=AF51,"Same",IF(AO51>AF51,"Increase","Decrease"))) -> Same | AQ51: =AN51*AF51 -> 353.4 | AR51: =AN51*AO51 -> 353.4 | AS51: =AR51-AQ51 -> 0
A52: 5218674 | B52: 5218674 | C52: DDEC01 | D52: Akzo DDC | E52: Armstead TR V/Matt Magnolia 10L | F52: Armstead TR V/Matt Magnolia 10L | H52: EA | I52: ITEM | J52: ITEM | K52: Paint | L52: 22.05 | M52: STD20 | N52: 3105 | R52: 26.94 | S52: 26.94 | T52: 594 | V52: 22.05 | W52: 16.47 | X52: =SUM(V52*T52) -> 13097.7 | Y52: =SUM(L52*T52) -> 13097.7 | Z52: =SUM(X52-Y52) -> 0 | AA52: 594 | AB52: =IFERROR(VLOOKUP(A52,'Tash Lookup'!A:E,3,FALSE),"") -> 11432.78 | AC52: =IFERROR(AA52-T52,"") -> 0 | AD52: Normal | AF52: 21.13 | AG52: =VLOOKUP(A52,Sheet1!$A$2:$C$1140,3,FALSE) -> 21.13 | AH52: 21.13 | AI52: =IF(ISNA(AH52),"Delete",IF(AH52=AF52,"Same",IF(AH52>AF52,"Increase","Decrease"))) -> Same | AJ52: =IFERROR(AA52*AF52,0) -> 12551.22 | AK52: =IFERROR(AA52*AH52,0) -> 12551.22 | AL52: Paint | AM52: Normal | AN52: 100 | AO52: 21.13 | AP52: =IF(AM52="Delete","Delete",IF(AO52=AF52,"Same",IF(AO52>AF52,"Increase","Decrease"))) -> Same | AQ52: =AN52*AF52 -> 2113 | AR52: =AN52*AO52 -> 2113 | AS52: =AR52-AQ52 -> 0
A53: 6365257 | B53: 6365257 | C53: DDEC01 | D53: Akzo DDC | E53: Ultragrime Huge Wipes Pack of 100 | F53: Ultragrime Huge Wipes Pack of 100 | H53: EA | I53: ITEM | J53: ITEM | K53: Paint | L53: 8.23 | M53: STD20 | N53: 3105 | R53: 8.23 | S53: 8.23 | T53: 570 | V53: 8.23 | W53: 8.23 | X53: =SUM(V53*T53) -> 4691.1 | Y53: =SUM(L53*T53) -> 4691.1 | Z53: =SUM(X53-Y53) -> 0 | AA53: 570 | AB53: =IFERROR(VLOOKUP(A53,'Tash Lookup'!A:E,3,FALSE),"") -> 4604.59 | AC53: =IFERROR(AA53-T53,"") -> 0 | AD53: Normal | AF53: 8.65 | AG53: =VLOOKUP(A53,Sheet1!$A$2:$C$1140,3,FALSE) -> 8.82 | AH53: 8.82 | AI53: =IF(ISNA(AH53),"Delete",IF(AH53=AF53,"Same",IF(AH53>AF53,"Increase","Decrease"))) -> Increase | AJ53: =IFERROR(AA53*AF53,0) -> 4930.5 | AK53: =IFERROR(AA53*AH53,0) -> 5027.4 | AL53: Sundries / 3rd Party | AM53: Normal | AN53: 225 | AO53: 8.82 | AP53: =IF(AM53="Delete","Delete",IF(AO53=AF53,"Same",IF(AO53>AF53,"Increase","Decrease"))) -> Increase | AQ53: =AN53*AF53 -> 1946.25 | AR53: =AN53*AO53 -> 1984.5 | AS53: =AR53-AQ53 -> 38.25
... A55: 5180449 | B55: 5180449 | C55: DDEC01 | D55: Akzo DDC | E55: Dulux TR W/S Ext U/Coat B/white 5L | F55: Dulux TR W/S Ext U/Coat B/white 5L | H55: EA | I55: ITEM | J55: ITEM | K55: Paint | L55: 38.32 | M55: STD20 | N55: 3105 | R55: 38.32 | S55: 38.32 | T55: 544 | V55: 38.32 | W55: 38.32 | X55: =SUM(V55*T55) -> 20846.08 | Y55: =SUM(L55*T55) -> 20846.08 | Z55: =SUM(X55-Y55) -> 0 | AA55: 544 | AB55: =IFERROR(VLOOKUP(A55,'Tash Lookup'!A:E,3,FALSE),"") -> 20525.88 | AC55: =IFERROR(AA55-T55,"") -> 0 | AD55: Normal | AF55: 36.44 | AG55: =VLOOKUP(A55,Sheet1!$A$2:$C$1140,3,FALSE) -> 36.44 | AH55: 36.44 | AI55: =IF(ISNA(AH55),"Delete",IF(AH55=AF55,"Same",IF(AH55>AF55,"Increase","Decrease"))) -> Same | AJ55: =IFERROR(AA55*AF55,0) -> 19823.36 | AK55: =IFERROR(AA55*AH55,0) -> 19823.36 | AL55: Paint | AM55: Normal | AN55: 329 | AO55: 36.44 | AP55: =IF(AM55="Delete","Delete",IF(AO55=AF55,"Same",IF(AO55>AF55,"Increase","Decrease"))) -> Same | AQ55: =AN55*AF55 -> 11988.76 | AR55: =AN55*AO55 -> 11988.76 | AS55: =AR55-AQ55 -> 0
A56: 6034079 | B56: 6034079 | C56: DDEC01 | D56: Akzo DDC | E56: Trade Brush - 2' | F56: Trade Brush - 2' | H56: EA | I56: ITEM | J56: ITEM | K56: Paint | L56: 1.91 | M56: STD20 | N56: 3105 | R56: 4.03 | S56: 4.03 | T56: 542 | V56: 1.91 | W56: 1.91 | X56: =SUM(V56*T56) -> 1035.22 | Y56: =SUM(L56*T56) -> 1035.22 | Z56: =SUM(X56-Y56) -> 0 | AA56: 542 | AB56: =IFERROR(VLOOKUP(A56,'Tash Lookup'!A:E,3,FALSE),"") -> 1026.37 | AC56: =IFERROR(AA56-T56,"") -> 0 | AD56: Normal | AF56: 1.72 | AG56: =VLOOKUP(A56,Sheet1!$A$2:$C$1140,3,FALSE) -> #N/A | AH56: #N/A | AI56: =IF(ISNA(AH56),"Delete",IF(AH56=AF56,"Same",IF(AH56>AF56,"Increase","Decrease"))) -> Delete | AJ56: =IFERROR(AA56*AF56,0) -> 932.24 | AK56: =IFERROR(AA56*AH56,0) -> 0 | AL56: Sundries / 3rd Party | AM56: Normal | AN56: 252 | AO56: 1.75 | AP56: =IF(AM56="Delete","Delete",IF(AO56=AF56,"Same",IF(AO56>AF56,"Increase","Decrease"))) -> Increase | AQ56: =AN56*AF56 -> 433.44 | AR56: =AN56*AO56 -> 441 | AS56: =AR56-AQ56 -> 7.56
A57: 6183866 | B57: 6183866 | C57: DDEC01 | D57: Akzo DDC | E57: DDC Medium Pile Woven Sleeve 9IN | F57: DDC Medium Pile Woven Sleeve 9IN | H57: EA | I57: ITEM | J57: ITEM | K57: Paint | L57: 2.05 | M57: STD20 | N57: 3105 | R57: 5.58 | S57: 5.58 | T57: 540 | V57: 2.05 | W57: 2.05 | X57: =SUM(V57*T57) -> 1107 | Y57: =SUM(L57*T57) -> 1107 | Z57: =SUM(X57-Y57) -> 0 | AA57: 540 | AB57: =IFERROR(VLOOKUP(A57,'Tash Lookup'!A:E,3,FALSE),"") -> 1096.41 | AC57: =IFERROR(AA57-T57,"") -> 0 | AD57: Normal | AF57: 2.05 | AG57: =VLOOKUP(A57,Sheet1!$A$2:$C$1140,3,FALSE) -> 2.09 | AH57: 2.09 | AI57: =IF(ISNA(AH57),"Delete",IF(AH57=AF57,"Same",IF(AH57>AF57,"Increase","Decrease"))) -> Increase | AJ57: =IFERROR(AA57*AF57,0) -> 1107 | AK57: =IFERROR(AA57*AH57,0) -> 1128.6 | AL57: Sundries / 3rd Party | AM57: Normal | AN57: 505 | AO57: 2.09 | AP57: =IF(AM57="Delete","Delete",IF(AO57=AF57,"Same",IF(AO57>AF57,"Increase","Decrease"))) -> Increase | AQ57: =AN57*AF57 -> 1035.25 | AR57: =AN57*AO57 -> 1055.45 | AS57: =AR57-AQ57 -> 20.2
A58: 5091026 | B58: 5091026 | C58: DDEC01 | D58: Akzo DDC | E58: Dulux TR Gloss PBW 5L | F58: Dulux TR Gloss PBW 5L | H58: EA | I58: ITEM | J58: ITEM | K58: Paint | L58: 25.83 | M58: STD20 | N58: 3105 | R58: 25.83 | S58: 25.83 | T58: 515 | V58: 25.83 | W58: 25.83 | X58: =SUM(V58*T58) -> 13302.45 | Y58: =SUM(L58*T58) -> 13302.45 | Z58: =SUM(X58-Y58) -> 0 | AA58: 515 | AB58: =IFERROR(VLOOKUP(A58,'Tash Lookup'!A:E,3,FALSE),"") -> 13189.47 | AC58: =IFERROR(AA58-T58,"") -> 0 | AD58: Normal | AF58: 26.59 | AG58: =VLOOKUP(A58,Sheet1!$A$2:$C$1140,3,FALSE) -> 26.59 | AH58: 26.59 | AI58: =IF(ISNA(AH58),"Delete",IF(AH58=AF58,"Same",IF(AH58>AF58,"Increase","Decrease"))) -> Same | AJ58: =IFERROR(AA58*AF58,0) -> 13693.85 | AK58: =IFERROR(AA58*AH58,0) -> 13693.85 | AL58: Paint | AM58: Normal | AN58: 192 | AO58: 26.59 | AP58: =IF(AM58="Delete","Delete",IF(AO58=AF58,"Same",IF(AO58>AF58,"Increase","Decrease"))) -> Same | AQ58: =AN58*AF58 -> 5105.28 | AR58: =AN58*AO58 -> 5105.28 | AS58: =AR58-AQ58 -> 0
...

Sheet Sheet1
A2: 5218583 | B2: Armstead TR Contract Matt Gardenia 10L | C2: 16.99
A3: 5218584 | B3: Armstead TR Contract Matt Magnolia 10L | C3: 17.47
A4: 5218585 | B4: Armstead TR Contract Matt Magnolia 15L | C4: 24.61
A5: 5219312 | B5: Armstead Trade Contract Matt Tinted Colours 10L | C5: 17.04
A6: 5218587 | B6: Armstead TR Contract Matt White 10L | C6: 12.5
A7: 5218588 | B7: Armstead TR Contract Matt White 15L | C7: 20.9
A8: 5196657 | B8: Dulux TR Drywall Primer Sealer 10L | C8: 35.34
A9: 5091283 | B9: Dulux TR Fast Matt Magnolia 10L | C9: 33
A10: 5090769 | B10: Dulux Trade Fast Matt Tinted Colours 10L | C10: 31.28
A11: 5091282 | B11: Dulux TR Fast Matt White 10L | C11: 30.37
A12: 5091671 | B12: Dulux TR AS Supermatt Almond White 10L | C12: 26.7
A13: 5091670 | B13: Dulux TR Supermatt Gardenia 10L | C13: 30
... A1140: 6188976 | B1140: Ronseal H/P Wood Filler White 550G | C1140: 11.17

Sheet Remove Old Items 
A1: No. | B1: Description | C1: Unit Cost
A2: 5025582A | B2: Sikkens Cetol BL Primer White 2.5L | C2: 34.21
A3: 5028159 | B3: DDC - SI CETOL NOVATOP 006 CHENE CLAIR 5L | C3: 61.99
A4: 5060367A | B4: Sikkens Rubbol XD Gloss White 2.5L | C4: 41.08
A5: 5074297A | B5: Rubbol satura wit 1l | C5: 17.99
A6: 5074298A | B6: Rubbol satura wit 2.5l | C6: 36.92
A7: 5077776A | B7: Poly Tr Stain Block 1L | C7: 15.61
A8: 5077788A | B8: Poly Tr Stain Block 2.5L | C8: 32.69
A9: 5081949A | B9: Dulux TR QD WD Primer U/Coat 2.5L | C9: 22.06
A10: 5081950A | B10: Dulux TR QD WD Primer U/Coat 5L | C10: 39.96
A11: 5081964A | B11: Dulux TR S/sheen PBW 5L | C11: 28.76
A12: 5081985A | B12: Dulux TR QD Opaque White 1L | C12: 15.48
A13: 5081986A | B13: Dulux TR QD Opaque White 2.5L | C13: 33.63
... A1747: 8188865 | B1747: Akzo DDC - DDC SHORT HANDLE STICK FRAME 4IN | C1747: 0.96558

Sheet Sheet3
A1: Item Number (global) | C1: Qty YTD 01/2023-12/2023
A2: 5074297 | B2: RUBBOL SATURA WIT 1L | C2: 1
A3: 5074298 | B3: RUBBOL SATURA WIT 2.5L | C3: 11
A4: 5074299 | B4: RUBBOL SATURA ZWART 1L | C4: 3
A5: 5077776 | B5: POLY TR STAIN BLOCK 1L | C5: 18
A6: 5077788 | B6: POLY TR STAIN BLOCK 2.5L | C6: 25
A7: 5081949 | B7: DULUX TR QD WD PRIMER U/COAT 2.5L | C7: 65
A8: 5081950 | B8: DULUX TR QD WD PRIMER U/COAT 5L | C8: 902
A9: 5081964 | B9: DULUX TR S/SHEEN PBW 5L | C9: 19
A10: 5081985 | B10: DULUX TR QD OPAQUE WHITE 1L | C10: 2
A11: 5081986 | B11: DULUX TR QD OPAQUE WHITE 2.5L | C11: 16
A12: 5081987 | B12: DULUX TR QD OPAQUE BLACK 1L | C12: 3
A13: 5081988 | B13: DULUX TR QD OPAQUE BLACK 2.5L | C13: 40
... A1599: 8002380 | B1599: REFUND HERITAGE TESTER POT | C1599: -5

Sheet Tash Lookup
A1: Item Number (global) | B1: SKU Name | C1: Sales All | D1: Qty YTD 01/2023-12/2023 | E1: Generic
A2: 5074297 | B2: RUBBOL SATURA WIT 1L | C2: 17.99 | D2: 1 | E2: =_xlfn.XLOOKUP(A2,'[1]query (5)'!$C:$C,'[1]query (5)'!$A:$A) -> #N/A
A3: 5074298 | B3: RUBBOL SATURA WIT 2.5L | C3: 406.11 | D3: 11 | E3: =_xlfn.XLOOKUP(A3,'[1]query (5)'!$C:$C,'[1]query (5)'!$A:$A) -> #N/A
A4: 5074299 | B4: RUBBOL SATURA ZWART 1L | C4: 55.46 | D4: 3 | E4: =_xlfn.XLOOKUP(A4,'[1]query (5)'!$C:$C,'[1]query (5)'!$A:$A) -> #N/A
A5: 5077776 | B5: POLY TR STAIN BLOCK 1L | C5: 275.27 | D5: 18 | E5: =_xlfn.XLOOKUP(A5,'[1]query (5)'!$C:$C,'[1]query (5)'!$A:$A) -> #N/A
A6: 5077788 | B6: POLY TR STAIN BLOCK 2.5L | C6: 815.26 | D6: 25 | E6: =_xlfn.XLOOKUP(A6,'[1]query (5)'!$C:$C,'[1]query (5)'!$A:$A) -> #N/A
A7: 5081949 | B7: DULUX TR QD WD PRIMER U/COAT 2.5L | C7: 1545.06 | D7: 66 | E7: =_xlfn.XLOOKUP(A7,'[1]query (5)'!$C:$C,'[1]query (5)'!$A:$A) -> #N/A
A8: 5081950 | B8: DULUX TR QD WD PRIMER U/COAT 5L | C8: 35280.97 | D8: 902 | E8: =_xlfn.XLOOKUP(A8,'[1]query (5)'!$C:$C,'[1]query (5)'!$A:$A) -> #N/A
A9: 5081964 | B9: DULUX TR S/SHEEN PBW 5L | C9: 546.43 | D9: 19 | E9: =_xlfn.XLOOKUP(A9,'[1]query (5)'!$C:$C,'[1]query (5)'!$A:$A) -> #N/A
A10: 5081985 | B10: DULUX TR QD OPAQUE WHITE 1L | C10: 30.96 | D10: 2 | E10: =_xlfn.XLOOKUP(A10,'[1]query (5)'!$C:$C,'[1]query (5)'!$A:$A) -> #N/A
A11: 5081986 | B11: DULUX TR QD OPAQUE WHITE 2.5L | C11: 546.11 | D11: 16 | E11: =_xlfn.XLOOKUP(A11,'[1]query (5)'!$C:$C,'[1]query (5)'!$A:$A) -> #N/A
A12: 5081987 | B12: DULUX TR QD OPAQUE BLACK 1L | C12: 46.44 | D12: 3 | E12: =_xlfn.XLOOKUP(A12,'[1]query (5)'!$C:$C,'[1]query (5)'!$A:$A) -> #N/A
A13: 5081988 | B13: DULUX TR QD OPAQUE BLACK 2.5L | C13: 1361.28 | D13: 40 | E13: =_xlfn.XLOOKUP(A13,'[1]query (5)'!$C:$C,'[1]query (5)'!$A:$A) -> #N/A
... A1632: 8002696 | B1632: DIAMONDMATTSCRATCHCARD | C1632: 0 | D1632: 9 | E1632: =_xlfn.XLOOKUP(A1632,'[1]query (5)'!$C:$C,'[1]query (5)'!$A:$A) -> #N/A
A1633: GROUPED | B1633: GROUPED | C1633: -56.84 | D1633: 0 | E1633: =_xlfn.XLOOKUP(A1633,'[1]query (5)'!$C:$C,'[1]query (5)'!$A:$A) -> #N/A
A1634: SUPPL GROUPED | B1634: SUPPL GROUPED | C1634: -131.07 | D1634: 0 | E1634: =_xlfn.XLOOKUP(A1634,'[1]query (5)'!$C:$C,'[1]query (5)'!$A:$A) -> #N/A
A1635: # | B1635: Not assigned | C1635: -625471.84 | D1635: 0 | E1635: =_xlfn.XLOOKUP(A1635,'[1]query (5)'!$C:$C,'[1]query (5)'!$A:$A) -> #N/A
A1636: 5090575 | C1636: 122.63 | D1636: 3
A1637: 5090590 | C1637: 504.29 | D1637: 15
A1638: 5090718 | C1638: 34785.6 | D1638: 932
A1639: 5090726 | C1639: 1323.76 | D1639: 120
A1640: 5090727 | C1640: 4691.4 | D1640: 216
A1641: 5090728 | C1641: 13776.83 | D1641: 375
A1642: 5090729 | C1642: 196.5 | D1642: 14
A1643: 5090732 | C1643: 680.69 | D1643: 41
A1644: 5090733 | C1644: 17120.65 | D1644: 512
A1645: 5090734 | C1645: 19986.55 | D1645: 365
A1646: 5090739 | C1646: 219.82 | D1646: 12
A1647: 5090740 | C1647: 1654.79 | D1647: 50
... A1759: 6412815 | C1759: 29.12 | D1759: 13
