Workbook

Sheet Workings 
L1: OLD | M1: NEW
A2: 6061706 | B2: CROW01 | C2: CROWN | D2: DE PROF CAULK WHITE 380ML | E2: CROWN - DE PROF CAULK WHITE 380ML | G2: 1.134 | H2: 1.11 | I2: 2408.9153 | J2: Down | L2: =SUM(G2*I2) -> 2731.71 | M2: =SUM(H2*I2) -> 2673.896 | O2: =SUM(M2:M807) -> 359066.93 | P2: =SUM(L2:L807) -> 366827.48 | Q2: =SUM(O2-P2) -> -7760.5576
A3: 5023891 | B3: CROW01 | C3: CROWN | D3: CRT Covermatt Obliterating Emulsion | E3: CROWN - CRT Covermatt Obliterating Emulsion | F3: White | G3: 23.76 | H3: 23.76 | I3: 1842 | J3: No Change | L3: =SUM(G3*I3) -> 43765.92 | M3: =SUM(H3*I3) -> 43765.92
A4: 6046432 | B4: CROW01 | C4: CROWN | D4: WA ANAGLYPTA PRECISION ROYAL OAK RD7000 | E4: CROWN - WA ANAGLYPTA PRECISION ROYAL OAK RD7000 | G4: 7.76 | H4: 7.76 | I4: 1597 | J4: No Change | L4: =SUM(G4*I4) -> 12392.72 | M4: =SUM(H4*I4) -> 12392.72
A5: 6058266 | B5: CROW01 | C5: CROWN | D5: DS FLUXAF POWER CLEAN 750ML | E5: CROWN - DS FLUXAF POWER CLEAN 750ML | G5: 7.98 | H5: 7.98 | I5: 1201 | J5: No Change | L5: =SUM(G5*I5) -> 9583.98 | M5: =SUM(H5*I5) -> 9583.98 | P5: 806 | Q5: total Skus YTD
A6: 6040482 | B6: CROW01 | C6: CROWN | D6: WA AS CREATION CASABLANCA 4 WALL | E6: CROWN - WA AS CREATION CASABLANCA 4 WALL | G6: 6.363 | H6: 6.55389 | I6: 941.44272 | J6: Up | L6: =SUM(G6*I6) -> 5990.4 | M6: =SUM(H6*I6) -> 6170.112 | P6: 666 | Q6: Up
A7: 5040579 | B7: CROW01 | C7: CROWN | D7: CRT Timonox Matt | E7: CROWN - CRT Timonox Matt | F7: Brilliant White | G7: 41.12 | H7: 41.12 | I7: 609 | J7: No Change | L7: =SUM(G7*I7) -> 25042.08 | M7: =SUM(H7*I7) -> 25042.08 | P7: 94 | Q7: No Change
A8: 5024010 | B8: CROW01 | C8: CROWN | D8: CRT Stronghold Masonry Smooth | E8: CROWN - CRT Stronghold Masonry Smooth | F8: Magnolia | G8: 20.32 | H8: 20.32 | I8: 540 | J8: No Change | L8: =SUM(G8*I8) -> 10972.8 | M8: =SUM(H8*I8) -> 10972.8 | P8: 46 | Q8: Down
A9: 6041133 | B9: CROW01 | C9: CROWN | D9: DS INDASA MTE MASKING TAPE 48MM | E9: CROWN - DS INDASA MTE MASKING TAPE 48MM | G9: 3.5 | H9: 3.3 | I9: 536 | J9: Down | L9: =SUM(G9*I9) -> 1876 | M9: =SUM(H9*I9) -> 1768.8
A10: 6061706 | B10: CROW01 | C10: CROWN | D10: DE PROF CAULK WHITE 380ML | E10: CROWN - DE PROF CAULK WHITE 380ML | G10: 1.134 | H10: 1.11 | I10: 437.84295 | J10: No Change | L10: =SUM(G10*I10) -> 496.51391 | M10: =SUM(H10*I10) -> 486.00568 | P10: =SUM(P6:P8) -> 806
A11: 5026956 | B11: CROW01 | C11: CROWN | D11: CRT Solvent-borne Full Gloss | E11: CROWN - CRT Solvent-borne Full Gloss | F11: White | G11: 25.72 | H11: 25.72 | I11: 434 | J11: No Change | L11: =SUM(G11*I11) -> 11162.48 | M11: =SUM(H11*I11) -> 11162.48
A12: 5024059 | B12: CROW01 | C12: CROWN | D12: CRT Vinyl Matt | E12: CROWN - CRT Vinyl Matt | F12: White | G12: 21.64 | H12: 21.64 | I12: 376 | J12: No Change | L12: =SUM(G12*I12) -> 8136.64 | M12: =SUM(H12*I12) -> 8136.64
A13: 6041126 | B13: CROW01 | C13: CROWN | D13: DS INDASA MTG MASKING TAPE 50MM 45MT | E13: CROWN - DS INDASA MTG MASKING TAPE 50MM 45MT | G13: 1.4 | H13: 1.4 | I13: 366 | J13: No Change | L13: =SUM(G13*I13) -> 512.4 | M13: =SUM(H13*I13) -> 512.4
A14: 5024174 | B14: CROW01 | C14: CROWN | D14: CRT Acrylic Primer Undercoat | E14: CROWN - CRT Acrylic Primer Undercoat | F14: White | G14: 18 | H14: 18 | I14: 325 | J14: No Change | L14: =SUM(G14*I14) -> 5850 | M14: =SUM(H14*I14) -> 5850
A15: 6062944 | B15: CROW01 | C15: CROWN | D15: DS Q1 CONTRACTOR MASKING TAPE 50M 48MM | E15: CROWN - DS Q1 CONTRACTOR MASKING TAPE 50M 48MM | G15: 2.1 | H15: 2.1 | I15: 297 | J15: No Change | L15: =SUM(G15*I15) -> 623.7 | M15: =SUM(H15*I15) -> 623.7
A16: 5027127 | B16: CROW01 | C16: CROWN | D16: CRT Solvent-borne Undercoat | E16: CROWN - CRT Solvent-borne Undercoat | F16: White | G16: 24.2 | H16: 24.2 | I16: 289 | J16: No Change | L16: =SUM(G16*I16) -> 6993.8 | M16: =SUM(H16*I16) -> 6993.8
A17: 5024026 | B17: CROW01 | C17: CROWN | D17: CRT Stronghold Masonry Smooth | E17: CROWN - CRT Stronghold Masonry Smooth | F17: White | G17: 20.32 | H17: 20.32 | I17: 258 | J17: No Change | L17: =SUM(G17*I17) -> 5242.56 | M17: =SUM(H17*I17) -> 5242.56
A18: 5027850 | B18: CROW01 | C18: CROWN | D18: MAC Powerkote Masonry Smooth | E18: CROWN - MAC Powerkote Masonry Smooth | F18: Magnolia | G18: 22.45 | H18: 23.12 | I18: 194 | J18: Up | L18: =SUM(G18*I18) -> 4355.3 | M18: =SUM(H18*I18) -> 4485.28
A19: 5094753 | B19: CROW01 | C19: CROWN | D19: CRT Alkali Resistant Primer PX4 - W/BASED | E19: CROWN - CRT Alkali Resistant Primer PX4 - W/BASED | F19: Off White | G19: 35.56 | H19: 35.56 | I19: 184 | J19: No Change | L19: =SUM(G19*I19) -> 6543.04 | M19: =SUM(H19*I19) -> 6543.04
A20: 5061839 | B20: CROW01 | C20: CROWN | D20: CRT Clean Extreme | E20: CROWN - CRT Clean Extreme | F20: Magnolia | G20: 25.97 | H20: 25.97 | I20: 177 | J20: No Change | L20: =SUM(G20*I20) -> 4596.69 | M20: =SUM(H20*I20) -> 4596.69
A21: 5025052 | B21: CROW01 | C21: CROWN | D21: MAC Eclipse | E21: CROWN - MAC Eclipse | F21: Magnolia | G21: 19.92 | H21: 20.52 | I21: 162 | J21: Up | L21: =SUM(G21*I21) -> 3227.04 | M21: =SUM(H21*I21) -> 3324.24
A22: 6055142 | B22: CROW01 | C22: CROWN | D22: DS ULTRAGRIME PRO XXL+MULTI WIPES 100PK | E22: CROWN - DS ULTRAGRIME PRO XXL+MULTI WIPES 100PK | G22: 13.7445 | H22: 13.5 | I22: 159.33646 | J22: Down | L22: =SUM(G22*I22) -> 2190 | M22: =SUM(H22*I22) -> 2151.0422
A23: 5025056 | B23: CROW01 | C23: CROWN | D23: MAC Eclipse | E23: CROWN - MAC Eclipse | F23: Brilliant White | G23: 18.27 | H23: 18.82 | I23: 158 | J23: Up | L23: =SUM(G23*I23) -> 2886.66 | M23: =SUM(H23*I23) -> 2973.56
A24: 5061965 | B24: CROW01 | C24: CROWN | D24: CRT Clean Extreme | E24: CROWN - CRT Clean Extreme | F24: White | G24: 25.04 | H24: 25.04 | I24: 152 | J24: No Change | L24: =SUM(G24*I24) -> 3806.08 | M24: =SUM(H24*I24) -> 3806.08
A25: 5090804 | B25: CROW01 | C25: CROWN | D25: CRT Fastflow Quick Dry Gloss | E25: CROWN - CRT Fastflow Quick Dry Gloss | F25: White | G25: 25.29 | H25: 26.05 | I25: 151 | J25: Up | L25: =SUM(G25*I25) -> 3818.79 | M25: =SUM(H25*I25) -> 3933.55
A26: 6042334 | B26: CROW01 | C26: CROWN | D26: DS PRODEC EXTRA LONG POLYESTER ROL 9IN | E26: CROWN - DS PRODEC EXTRA LONG POLYESTER ROL 9IN | G26: 3.402 | H26: 3.4 | I26: 149.91182 | J26: No Change | L26: =SUM(G26*I26) -> 510 | M26: =SUM(H26*I26) -> 509.70018
A27: 5090816 | B27: CROW01 | C27: CROWN | D27: CRT Fastflow Quick Dry Primer Undercoat | E27: CROWN - CRT Fastflow Quick Dry Primer Undercoat | F27: White | G27: 26 | H27: 26 | I27: 147 | J27: No Change | L27: =SUM(G27*I27) -> 3822 | M27: =SUM(H27*I27) -> 3822
A28: 6055912 | B28: CROW01 | C28: CROWN | D28: DS TRIMACO BROWN MASKING PAPER 180FT | E28: CROWN - DS TRIMACO BROWN MASKING PAPER 180FT | G28: 5.25 | H28: 5.4075 | I28: 140 | J28: Up | L28: =SUM(G28*I28) -> 735 | M28: =SUM(H28*I28) -> 757.05
A29: 5024213 | B29: CROW01 | C29: CROWN | D29: CRT Silk | E29: CROWN - CRT Silk | F29: Magnolia | G29: 28.09 | H29: 28.09 | I29: 138 | J29: No Change | L29: =SUM(G29*I29) -> 3876.42 | M29: =SUM(H29*I29) -> 3876.42
A30: 5064671 | B30: CROW01 | C30: CROWN | D30: CRT Acrylic Eggshell | E30: CROWN - CRT Acrylic Eggshell | F30: Magnolia | G30: 26.14 | H30: 26.14 | I30: 135 | J30: No Change | L30: =SUM(G30*I30) -> 3528.9 | M30: =SUM(H30*I30) -> 3528.9
A31: 6055707 | B31: CROW01 | C31: CROWN | D31: DS OAKEY FLEXIBLE FINISH PADS EX MED/CRS | E31: CROWN - DS OAKEY FLEXIBLE FINISH PADS EX MED/CRS | G31: 1.11 | H31: 1.11 | I31: 133 | J31: No Change | L31: =SUM(G31*I31) -> 147.63 | M31: =SUM(H31*I31) -> 147.63
A32: 5093395 | B32: CROW01 | C32: CROWN | D32: CRT Clean Extreme Mould Inhibiting Matt | E32: CROWN - CRT Clean Extreme Mould Inhibiting Matt | F32: White | G32: 33.87 | H32: 33.87 | I32: 125 | J32: No Change | L32: =SUM(G32*I32) -> 4233.75 | M32: =SUM(H32*I32) -> 4233.75
A33: 5091987 | B33: CROW01 | C33: CROWN | D33: CRT Fastflow QD Satin | E33: CROWN - CRT Fastflow QD Satin | F33: White | G33: 28 | H33: 28 | I33: 122 | J33: No Change | L33: =SUM(G33*I33) -> 3416 | M33: =SUM(H33*I33) -> 3416
A34: 6061964 | B34: CROW01 | C34: CROWN | D34: DS HAMILTON MEDIUM PILE ROLLER 4IN 10PK | E34: CROWN - DS HAMILTON MEDIUM PILE ROLLER 4IN 10PK | G34: 4.095 | H34: 4.1 | I34: 119.1453 | J34: Up | L34: =SUM(G34*I34) -> 487.9 | M34: =SUM(H34*I34) -> 488.49573
A35: 5026990 | B35: CROW01 | C35: CROWN | D35: CRT Solvent-borne Full Gloss | E35: CROWN - CRT Solvent-borne Full Gloss | F35: Brilliant White | G35: 19.68 | H35: 20.27 | I35: 118 | J35: Up | L35: =SUM(G35*I35) -> 2322.24 | M35: =SUM(H35*I35) -> 2391.86
A36: 6040483 | B36: CROW01 | C36: CROWN | D36: WA AS CREATION CASABLANCA 4 WALL | E36: CROWN - WA AS CREATION CASABLANCA 4 WALL | G36: 5.25 | H36: 5.4075 | I36: 117.71429 | J36: Up | L36: =SUM(G36*I36) -> 618 | M36: =SUM(H36*I36) -> 636.54
A37: 5073961 | B37: CROW01 | C37: CROWN | D37: ST RUST INHIB PRIMER GREY 2.5L | E37: CROWN - ST RUST INHIB PRIMER GREY 2.5L | G37: 44.3209 | H37: 40 | I37: 112.99771 | J37: Down | L37: =SUM(G37*I37) -> 5008.16 | M37: =SUM(H37*I37) -> 4519.9082
A38: 6040125 | B38: CROW01 | C38: CROWN | D38: WA ANAGLYPTA TEXT VINYL WILL BO RD804301 | E38: CROWN - WA ANAGLYPTA TEXT VINYL WILL BO RD804301 | G38: 4.94 | H38: 5.0882 | I38: 107 | J38: Up | L38: =SUM(G38*I38) -> 528.58 | M38: =SUM(H38*I38) -> 544.4374
A39: 6055201 | B39: CROW01 | C39: CROWN | D39: DE ESS PAINT BRUSH 2IN(12) EACH | E39: CROWN - DE ESS PAINT BRUSH 2IN(12) EACH | G39: 1.42 | H39: 1.42 | I39: 103 | J39: No Change | L39: =SUM(G39*I39) -> 146.26 | M39: =SUM(H39*I39) -> 146.26
A40: 6062917 | B40: CROW01 | C40: CROWN | D40: WA FINE DECOR CONTRACTOR BOOK 23 A | E40: CROWN - WA FINE DECOR CONTRACTOR BOOK 23 A | G40: 10.5 | H40: 10.815 | I40: 102.85714 | J40: Up | L40: =SUM(G40*I40) -> 1080 | M40: =SUM(H40*I40) -> 1112.4
...

Sheet Crown Aug Uploads 
A1: Enter your Item No We can't have duplicates in the system so if the cell highlights blue, you need to add ; at the end enough times to make unique Limited to 20 characters, yellow if more than this, need to cut down | B1: Enter your number (without any ; if you needed to add any in the 'No' field for duplicates) Again limited to 20 characters, need to cut down if yellow (Might be same as column A) | C1: Enter Vendor Number from Vendor List (new ERP number) | D1: Enter the suppliers name (doesn't need to be full legal one, this is just for description | E1: Paste in the suppliers description of the item | F1: Drag formula down after completing D & E Formula will combine the prior to cells We are though restricted to 50 characters so if the cell highlights in yellow it's too long, need to cut down, or move excess to description 2 column | G1: Enter if need more space to describe the Item | H1: Enter unit of measure | I1: Enter either "ITEM" or "PLANT" | J1: Enter "EXT-PLANT" or "ITEM" | K1: Enter category code to help group the items together, see "Category Code" for ones we've used so far Can add to this list though | L1: September 2022 Price | M1: Enter "STD20" unless you know it's not Vatable Alternatively, "REDUCED" or "ZERO" | N1: Enter a cost code for materials or plant (unless it's an overhead like stationery in which case can leave blank) | O1: Updated Template Pricing March 2023 | P1: QTY PURCHASED 2022 | Q1: June 2023 Price | R1: New Cost from Aug 2024 | S1: QTY PURCHASED 2024
A2: 6061706 | B2: 6061706 | C2: CROW01 | D2: CROWN | E2: =_xlfn.XLOOKUP(B2,Sheet1!A:A,Sheet1!B:B) -> DE PROF CAULK WHITE 380ML | F2: =D2&" - "&E2 -> CROWN - DE PROF CAULK WHITE 380ML | H2: Each | I2: Item | J2: Item | K2: Paint | M2: STD20 | N2: 3105 | O2: =_xlfn.XLOOKUP(B2,Sheet1!A:A,Sheet1!E:E) -> 1.08 | P2: =_xlfn.XLOOKUP(A2,Sheet2!F:F,Sheet2!H:H) -> 5364.9352 | Q2: =O2*1.05 -> 1.134 | R2: =_xlfn.XLOOKUP(B2,Sheet4!B:B,Sheet4!D:D) -> 1.11 | S2: 2408.9153 | T2: =IF(Q2>=R2,"No Change","Up") -> No Change | V2: =SUM(Q2*S2) -> 2731.71 | W2: =SUM(R2*S2) -> 2673.896
A3: 5023891 | B3: 5023891 | C3: CROW01 | D3: CROWN | E3: =_xlfn.XLOOKUP(B3,Sheet1!A:A,Sheet1!B:B) -> CRT Covermatt Obliterating Emulsion | F3: =D3&" - "&E3 -> CROWN - CRT Covermatt Obliterating Emulsion | G3: =_xlfn.XLOOKUP(B3,Sheet1!A:A,Sheet1!C:C) -> White | H3: =_xlfn.XLOOKUP(B3,Sheet1!A:A,Sheet1!D:D) -> 10L | I3: Item | J3: Item | K3: Paint | L3: 23.07 | M3: STD20 | N3: 3105 | O3: =_xlfn.XLOOKUP(B3,Sheet1!A:A,Sheet1!E:E) -> 23.07 | P3: =_xlfn.XLOOKUP(A3,Sheet2!F:F,Sheet2!H:H) -> 4058.7356 | Q3: =_xlfn.XLOOKUP(B3,April23!B:B,April23!D:D) -> 23.76 | R3: =_xlfn.XLOOKUP(B3,Sheet3!B:B,Sheet3!D:D) -> 23.76 | S3: 1842 | T3: =IF(Q3>=R3,"No Change","Up") -> No Change | V3: =SUM(Q3*S3) -> 43765.92 | W3: =SUM(R3*S3) -> 43765.92
A4: 6046432 | B4: 6046432 | C4: CROW01 | D4: CROWN | E4: =_xlfn.XLOOKUP(B4,Sheet1!A:A,Sheet1!B:B) -> WA ANAGLYPTA PRECISION ROYAL OAK RD7000 | F4: =D4&" - "&E4 -> CROWN - WA ANAGLYPTA PRECISION ROYAL OAK RD7000 | H4: Each | I4: Item | J4: Item | K4: Paint | L4: 7.53 | M4: STD20 | N4: 3105 | O4: =_xlfn.XLOOKUP(B4,Sheet1!A:A,Sheet1!E:E) -> 7.53 | P4: =_xlfn.XLOOKUP(A4,Sheet2!F:F,Sheet2!H:H) -> 1044.4422 | Q4: =_xlfn.XLOOKUP(B4,April23!B:B,April23!D:D) -> 7.76 | R4: =_xlfn.XLOOKUP(B4,Sheet4!B:B,Sheet4!D:D) -> 7.76 | S4: 1597 | T4: =IF(Q4>=R4,"No Change","Up") -> No Change | V4: =SUM(Q4*S4) -> 12392.72 | W4: =SUM(R4*S4) -> 12392.72
A5: 6058266 | B5: 6058266 | C5: CROW01 | D5: CROWN | E5: =_xlfn.XLOOKUP(B5,Sheet1!A:A,Sheet1!B:B) -> DS FLUXAF POWER CLEAN 750ML | F5: =D5&" - "&E5 -> CROWN - DS FLUXAF POWER CLEAN 750ML | H5: Each | I5: Item | J5: Item | K5: Paint | M5: STD20 | N5: 3105 | O5: =_xlfn.XLOOKUP(B5,Sheet1!A:A,Sheet1!E:E) -> 7.6 | P5: =_xlfn.XLOOKUP(A5,Sheet2!F:F,Sheet2!H:H) -> 3511.4342 | Q5: =O5*1.05 -> 7.98 | R5: 7.98 | S5: 1201 | T5: =IF(Q5>=R5,"No Change","Up") -> No Change | V5: =SUM(Q5*S5) -> 9583.98 | W5: =SUM(R5*S5) -> 9583.98
A6: 6040482 | B6: 6040482 | C6: CROW01 | D6: CROWN | E6: =_xlfn.XLOOKUP(B6,Sheet1!A:A,Sheet1!B:B) -> WA AS CREATION CASABLANCA 4 WALL | F6: =D6&" - "&E6 -> CROWN - WA AS CREATION CASABLANCA 4 WALL | H6: Each | I6: Item | J6: Item | K6: Paint | M6: STD20 | N6: 3105 | O6: =_xlfn.XLOOKUP(B6,Sheet1!A:A,Sheet1!E:E) -> 6.06 | P6: =_xlfn.XLOOKUP(A6,Sheet2!F:F,Sheet2!H:H) -> 789.9802 | Q6: =O6*1.05 -> 6.363 | R6: =Q6*1.03 -> 6.55389 | S6: 941.44272 | T6: =IF(Q6>=R6,"No Change","Up") -> Up | V6: =SUM(Q6*S6) -> 5990.4 | W6: =SUM(R6*S6) -> 6170.112
A7: 5040579 | B7: 5040579 | C7: CROW01 | D7: CROWN | E7: =_xlfn.XLOOKUP(B7,Sheet1!A:A,Sheet1!B:B) -> CRT Timonox Matt | F7: =D7&" - "&E7 -> CROWN - CRT Timonox Matt | G7: =_xlfn.XLOOKUP(B7,Sheet1!A:A,Sheet1!C:C) -> Brilliant White | H7: =_xlfn.XLOOKUP(B7,Sheet1!A:A,Sheet1!D:D) -> 5L | I7: Item | J7: Item | K7: Paint | L7: 50.41 | M7: STD20 | N7: 3105 | O7: =_xlfn.XLOOKUP(B7,Sheet1!A:A,Sheet1!E:E) -> 50.41 | P7: =_xlfn.XLOOKUP(A7,Sheet2!F:F,Sheet2!H:H) -> 978.03214 | Q7: =_xlfn.XLOOKUP(B7,April23!B:B,April23!D:D) -> 41.12 | R7: =_xlfn.XLOOKUP(B7,Sheet3!B:B,Sheet3!D:D) -> 41.12 | S7: 609 | T7: =IF(Q7>=R7,"No Change","Up") -> No Change | V7: =SUM(Q7*S7) -> 25042.08 | W7: =SUM(R7*S7) -> 25042.08
A8: 5024010 | B8: 5024010 | C8: CROW01 | D8: CROWN | E8: =_xlfn.XLOOKUP(B8,Sheet1!A:A,Sheet1!B:B) -> CRT Stronghold Masonry Smooth | F8: =D8&" - "&E8 -> CROWN - CRT Stronghold Masonry Smooth | G8: =_xlfn.XLOOKUP(B8,Sheet1!A:A,Sheet1!C:C) -> Magnolia | H8: =_xlfn.XLOOKUP(B8,Sheet1!A:A,Sheet1!D:D) -> 5L | I8: Item | J8: Item | K8: Paint | L8: 19.73 | M8: STD20 | N8: 3105 | O8: =_xlfn.XLOOKUP(B8,Sheet1!A:A,Sheet1!E:E) -> 19.73 | P8: =_xlfn.XLOOKUP(A8,Sheet2!F:F,Sheet2!H:H) -> 410.59199 | Q8: =_xlfn.XLOOKUP(B8,April23!B:B,April23!D:D) -> 20.32 | R8: =_xlfn.XLOOKUP(B8,Sheet3!B:B,Sheet3!D:D) -> 20.32 | S8: 540 | T8: =IF(Q8>=R8,"No Change","Up") -> No Change | V8: =SUM(Q8*S8) -> 10972.8 | W8: =SUM(R8*S8) -> 10972.8
A9: 6041133 | B9: 6041133 | C9: CROW01 | D9: CROWN | E9: =_xlfn.XLOOKUP(B9,Sheet1!A:A,Sheet1!B:B) -> DS INDASA MTE MASKING TAPE 48MM | F9: =D9&" - "&E9 -> CROWN - DS INDASA MTE MASKING TAPE 48MM | H9: Each | I9: Item | J9: Item | K9: Paint | L9: 3.79 | M9: STD20 | N9: 3105 | O9: =_xlfn.XLOOKUP(B9,Sheet1!A:A,Sheet1!E:E) -> 3.79 | P9: =_xlfn.XLOOKUP(A9,Sheet2!F:F,Sheet2!H:H) -> 907.52507 | Q9: =_xlfn.XLOOKUP(B9,April23!B:B,April23!D:D) -> 3.5 | R9: 3.3 | S9: 536 | T9: Down | V9: =SUM(Q9*S9) -> 1876 | W9: =SUM(R9*S9) -> 1768.8
A10: 6061706 | B10: 6061706 | C10: CROW01 | D10: CROWN | E10: =_xlfn.XLOOKUP(B10,Sheet1!A:A,Sheet1!B:B) -> DE PROF CAULK WHITE 380ML | F10: =D10&" - "&E10 -> CROWN - DE PROF CAULK WHITE 380ML | H10: Each | I10: Item | J10: Item | K10: Paint | M10: STD20 | N10: 3105 | O10: =_xlfn.XLOOKUP(B10,Sheet1!A:A,Sheet1!E:E) -> 1.08 | P10: =_xlfn.XLOOKUP(A10,Sheet2!F:F,Sheet2!H:H) -> 5364.9352 | Q10: =O10*1.05 -> 1.134 | R10: =_xlfn.XLOOKUP(B10,Sheet4!B:B,Sheet4!D:D) -> 1.11 | S10: 437.84295 | T10: =IF(Q10>=R10,"No Change","Up") -> No Change | V10: =SUM(Q10*S10) -> 496.51391 | W10: =SUM(R10*S10) -> 486.00568
A11: 5026956 | B11: 5026956 | C11: CROW01 | D11: CROWN | E11: =_xlfn.XLOOKUP(B11,Sheet1!A:A,Sheet1!B:B) -> CRT Solvent-borne Full Gloss | F11: =D11&" - "&E11 -> CROWN - CRT Solvent-borne Full Gloss | G11: =_xlfn.XLOOKUP(B11,Sheet1!A:A,Sheet1!C:C) -> White | H11: =_xlfn.XLOOKUP(B11,Sheet1!A:A,Sheet1!D:D) -> 5L | I11: Item | J11: Item | K11: Paint | L11: 16.32 | M11: STD20 | N11: 3105 | O11: =_xlfn.XLOOKUP(B11,Sheet1!A:A,Sheet1!E:E) -> 16.32 | P11: =_xlfn.XLOOKUP(A11,Sheet2!F:F,Sheet2!H:H) -> 1494.5821 | Q11: =_xlfn.XLOOKUP(B11,April23!B:B,April23!D:D) -> 25.72 | R11: =_xlfn.XLOOKUP(B11,Sheet3!B:B,Sheet3!D:D) -> 25.72 | S11: 434 | T11: =IF(Q11>=R11,"No Change","Up") -> No Change | V11: =SUM(Q11*S11) -> 11162.48 | W11: =SUM(R11*S11) -> 11162.48
A12: 5024059 | B12: 5024059 | C12: CROW01 | D12: CROWN | E12: =_xlfn.XLOOKUP(B12,Sheet1!A:A,Sheet1!B:B) -> CRT Vinyl Matt | F12: =D12&" - "&E12 -> CROWN - CRT Vinyl Matt | G12: =_xlfn.XLOOKUP(B12,Sheet1!A:A,Sheet1!C:C) -> White | H12: =_xlfn.XLOOKUP(B12,Sheet1!A:A,Sheet1!D:D) -> 10L | I12: Item | J12: Item | K12: Paint | L12: 21.01 | M12: STD20 | N12: 3105 | O12: =_xlfn.XLOOKUP(B12,Sheet1!A:A,Sheet1!E:E) -> 21.01 | P12: =_xlfn.XLOOKUP(A12,Sheet2!F:F,Sheet2!H:H) -> 1135.9324 | Q12: =_xlfn.XLOOKUP(B12,April23!B:B,April23!D:D) -> 21.64 | R12: =_xlfn.XLOOKUP(B12,Sheet3!B:B,Sheet3!D:D) -> 21.64 | S12: 376 | T12: =IF(Q12>=R12,"No Change","Up") -> No Change | V12: =SUM(Q12*S12) -> 8136.64 | W12: =SUM(R12*S12) -> 8136.64
A13: 6041126 | B13: 6041126 | C13: CROW01 | D13: CROWN | E13: =_xlfn.XLOOKUP(B13,Sheet1!A:A,Sheet1!B:B) -> DS INDASA MTG MASKING TAPE 50MM 45MT | F13: =D13&" - "&E13 -> CROWN - DS INDASA MTG MASKING TAPE 50MM 45MT | H13: Each | I13: Item | J13: Item | K13: Paint | L13: 1.33 | M13: STD20 | N13: 3105 | O13: =_xlfn.XLOOKUP(B13,Sheet1!A:A,Sheet1!E:E) -> 1.33 | P13: =_xlfn.XLOOKUP(A13,Sheet2!F:F,Sheet2!H:H) -> 2287.0602 | Q13: =_xlfn.XLOOKUP(B13,April23!B:B,April23!D:D) -> 1.4 | R13: =_xlfn.XLOOKUP(B13,Sheet4!B:B,Sheet4!D:D) -> 1.4 | S13: 366 | T13: =IF(Q13>=R13,"No Change","Up") -> No Change | V13: =SUM(Q13*S13) -> 512.4 | W13: =SUM(R13*S13) -> 512.4
A14: 5024174 | B14: 5024174 | C14: CROW01 | D14: CROWN | E14: =_xlfn.XLOOKUP(B14,Sheet1!A:A,Sheet1!B:B) -> CRT Acrylic Primer Undercoat | F14: =D14&" - "&E14 -> CROWN - CRT Acrylic Primer Undercoat | G14: =_xlfn.XLOOKUP(B14,Sheet1!A:A,Sheet1!C:C) -> White | H14: =_xlfn.XLOOKUP(B14,Sheet1!A:A,Sheet1!D:D) -> 5L | I14: Item | J14: Item | K14: Paint | L14: 25.39 | M14: STD20 | N14: 3105 | O14: =_xlfn.XLOOKUP(B14,Sheet1!A:A,Sheet1!E:E) -> 25.39 | P14: =_xlfn.XLOOKUP(A14,Sheet2!F:F,Sheet2!H:H) -> 895.60181 | Q14: =_xlfn.XLOOKUP(B14,April23!B:B,April23!D:D) -> 18 | R14: =_xlfn.XLOOKUP(B14,Sheet3!B:B,Sheet3!D:D) -> 18 | S14: 325 | T14: =IF(Q14>=R14,"No Change","Up") -> No Change | V14: =SUM(Q14*S14) -> 5850 | W14: =SUM(R14*S14) -> 5850
A15: 6062944 | B15: 6062944 | C15: CROW01 | D15: CROWN | E15: =_xlfn.XLOOKUP(B15,Sheet1!A:A,Sheet1!B:B) -> DS Q1 CONTRACTOR MASKING TAPE 50M 48MM | F15: =D15&" - "&E15 -> CROWN - DS Q1 CONTRACTOR MASKING TAPE 50M 48MM | H15: Each | I15: Item | J15: Item | K15: Paint | M15: STD20 | N15: 3105 | O15: =_xlfn.XLOOKUP(B15,Sheet1!A:A,Sheet1!E:E) -> 2 | Q15: =O15*1.05 -> 2.1 | R15: 2.1 | S15: 297 | T15: =IF(Q15>=R15,"No Change","Up") -> No Change | V15: =SUM(Q15*S15) -> 623.7 | W15: =SUM(R15*S15) -> 623.7
A16: 5027127 | B16: 5027127 | C16: CROW01 | D16: CROWN | E16: =_xlfn.XLOOKUP(B16,Sheet1!A:A,Sheet1!B:B) -> CRT Solvent-borne Undercoat | F16: =D16&" - "&E16 -> CROWN - CRT Solvent-borne Undercoat | G16: =_xlfn.XLOOKUP(B16,Sheet1!A:A,Sheet1!C:C) -> White | H16: =_xlfn.XLOOKUP(B16,Sheet1!A:A,Sheet1!D:D) -> 5L | I16: Item | J16: Item | K16: Paint | L16: 16.32 | M16: STD20 | N16: 3105 | O16: =_xlfn.XLOOKUP(B16,Sheet1!A:A,Sheet1!E:E) -> 16.32 | P16: =_xlfn.XLOOKUP(A16,Sheet2!F:F,Sheet2!H:H) -> 530.75797 | Q16: =_xlfn.XLOOKUP(B16,April23!B:B,April23!D:D) -> 24.2 | R16: =_xlfn.XLOOKUP(B16,Sheet3!B:B,Sheet3!D:D) -> 24.2 | S16: 289 | T16: =IF(Q16>=R16,"No Change","Up") -> No Change | V16: =SUM(Q16*S16) -> 6993.8 | W16: =SUM(R16*S16) -> 6993.8
A17: 5024026 | B17: 5024026 | C17: CROW01 | D17: CROWN | E17: =_xlfn.XLOOKUP(B17,Sheet1!A:A,Sheet1!B:B) -> CRT Stronghold Masonry Smooth | F17: =D17&" - "&E17 -> CROWN - CRT Stronghold Masonry Smooth | G17: =_xlfn.XLOOKUP(B17,Sheet1!A:A,Sheet1!C:C) -> White | H17: =_xlfn.XLOOKUP(B17,Sheet1!A:A,Sheet1!D:D) -> 5L | I17: Item | J17: Item | K17: Paint | L17: 19.73 | M17: STD20 | N17: 3105 | O17: =_xlfn.XLOOKUP(B17,Sheet1!A:A,Sheet1!E:E) -> 19.73 | P17: =_xlfn.XLOOKUP(A17,Sheet2!F:F,Sheet2!H:H) -> 211.16574 | Q17: =_xlfn.XLOOKUP(B17,April23!B:B,April23!D:D) -> 20.32 | R17: =_xlfn.XLOOKUP(B17,Sheet3!B:B,Sheet3!D:D) -> 20.32 | S17: 258 | T17: =IF(Q17>=R17,"No Change","Up") -> No Change | V17: =SUM(Q17*S17) -> 5242.56 | W17: =SUM(R17*S17) -> 5242.56
A18: 5027850 | B18: 5027850 | C18: CROW01 | D18: CROWN | E18: =_xlfn.XLOOKUP(B18,Sheet1!A:A,Sheet1!B:B) -> MAC Powerkote Masonry Smooth | F18: =D18&" - "&E18 -> CROWN - MAC Powerkote Masonry Smooth | G18: =_xlfn.XLOOKUP(B18,Sheet1!A:A,Sheet1!C:C) -> Magnolia | H18: =_xlfn.XLOOKUP(B18,Sheet1!A:A,Sheet1!D:D) -> 5L | I18: Item | J18: Item | K18: Paint | L18: 18.7 | M18: STD20 | N18: 3105 | O18: =_xlfn.XLOOKUP(B18,Sheet1!A:A,Sheet1!E:E) -> 18.7 | P18: =_xlfn.XLOOKUP(A18,Sheet2!F:F,Sheet2!H:H) -> 48.109091 | Q18: =_xlfn.XLOOKUP(B18,April23!B:B,April23!D:D) -> 22.45 | R18: =_xlfn.XLOOKUP(B18,Sheet3!B:B,Sheet3!D:D) -> 23.12 | S18: 194 | T18: =IF(Q18>=R18,"No Change","Up") -> Up | V18: =SUM(Q18*S18) -> 4355.3 | W18: =SUM(R18*S18) -> 4485.28
A19: 5094753 | B19: 5094753 | C19: CROW01 | D19: CROWN | E19: =_xlfn.XLOOKUP(B19,Sheet1!A:A,Sheet1!B:B) -> CRT Alkali Resistant Primer PX4 - W/BASED | F19: =D19&" - "&E19 -> CROWN - CRT Alkali Resistant Primer PX4 - W/BASED | G19: =_xlfn.XLOOKUP(B19,Sheet1!A:A,Sheet1!C:C) -> Off White | H19: =_xlfn.XLOOKUP(B19,Sheet1!A:A,Sheet1!D:D) -> 5L | I19: Item | J19: Item | K19: Paint | L19: 25.54 | M19: STD20 | N19: 3105 | O19: =_xlfn.XLOOKUP(B19,Sheet1!A:A,Sheet1!E:E) -> 25.54 | P19: =_xlfn.XLOOKUP(A19,Sheet2!F:F,Sheet2!H:H) -> 199.07087 | Q19: =_xlfn.XLOOKUP(B19,April23!B:B,April23!D:D) -> 35.56 | R19: =Q19 -> 35.56 | S19: 184 | T19: =IF(Q19>=R19,"No Change","Up") -> No Change | V19: =SUM(Q19*S19) -> 6543.04 | W19: =SUM(R19*S19) -> 6543.04
A20: 5061839 | B20: 5061839 | C20: CROW01 | D20: CROWN | E20: =_xlfn.XLOOKUP(B20,Sheet1!A:A,Sheet1!B:B) -> CRT Clean Extreme | F20: =D20&" - "&E20 -> CROWN - CRT Clean Extreme | G20: =_xlfn.XLOOKUP(B20,Sheet1!A:A,Sheet1!C:C) -> Magnolia | H20: =_xlfn.XLOOKUP(B20,Sheet1!A:A,Sheet1!D:D) -> 5L | I20: Item | J20: Item | K20: Paint | L20: 24.9 | M20: STD20 | N20: 3105 | O20: =_xlfn.XLOOKUP(B20,Sheet1!A:A,Sheet1!E:E) -> 24.9 | P20: =_xlfn.XLOOKUP(A20,Sheet2!F:F,Sheet2!H:H) -> 253.13012 | Q20: =_xlfn.XLOOKUP(B20,April23!B:B,April23!D:D) -> 25.97 | R20: =Q20 -> 25.97 | S20: 177 | T20: =IF(Q20>=R20,"No Change","Up") -> No Change | V20: =SUM(Q20*S20) -> 4596.69 | W20: =SUM(R20*S20) -> 4596.69
A21: 5025052 | B21: 5025052 | C21: CROW01 | D21: CROWN | E21: =_xlfn.XLOOKUP(B21,Sheet1!A:A,Sheet1!B:B) -> MAC Eclipse | F21: =D21&" - "&E21 -> CROWN - MAC Eclipse | G21: =_xlfn.XLOOKUP(B21,Sheet1!A:A,Sheet1!C:C) -> Magnolia | H21: =_xlfn.XLOOKUP(B21,Sheet1!A:A,Sheet1!D:D) -> 10L | I21: Item | J21: Item | K21: Paint | L21: 18.16 | M21: STD20 | N21: 3105 | O21: =_xlfn.XLOOKUP(B21,Sheet1!A:A,Sheet1!E:E) -> 18.16 | P21: =_xlfn.XLOOKUP(A21,Sheet2!F:F,Sheet2!H:H) -> 485.89042 | Q21: =_xlfn.XLOOKUP(B21,April23!B:B,April23!D:D) -> 19.92 | R21: =_xlfn.XLOOKUP(B21,Sheet3!B:B,Sheet3!D:D) -> 20.52 | S21: 162 | T21: =IF(Q21>=R21,"No Change","Up") -> Up | V21: =SUM(Q21*S21) -> 3227.04 | W21: =SUM(R21*S21) -> 3324.24
A22: 6055142 | B22: 6055142 | C22: CROW01 | D22: CROWN | E22: =_xlfn.XLOOKUP(B22,Sheet1!A:A,Sheet1!B:B) -> DS ULTRAGRIME PRO XXL+MULTI WIPES 100PK | F22: =D22&" - "&E22 -> CROWN - DS ULTRAGRIME PRO XXL+MULTI WIPES 100PK | H22: Each | I22: Item | J22: Item | K22: Paint | M22: STD20 | N22: 3105 | O22: =_xlfn.XLOOKUP(B22,Sheet1!A:A,Sheet1!E:E) -> 13.09 | P22: =_xlfn.XLOOKUP(A22,Sheet2!F:F,Sheet2!H:H) -> 188.64706 | Q22: =O22*1.05 -> 13.7445 | R22: 13.5 | S22: 159.33646 | T22: Down | V22: =SUM(Q22*S22) -> 2190 | W22: =SUM(R22*S22) -> 2151.0422
A23: 5025056 | B23: 5025056 | C23: CROW01 | D23: CROWN | E23: =_xlfn.XLOOKUP(B23,Sheet1!A:A,Sheet1!B:B) -> MAC Eclipse | F23: =D23&" - "&E23 -> CROWN - MAC Eclipse | G23: =_xlfn.XLOOKUP(B23,Sheet1!A:A,Sheet1!C:C) -> Brilliant White | H23: =_xlfn.XLOOKUP(B23,Sheet1!A:A,Sheet1!D:D) -> 10L | I23: Item | J23: Item | K23: Paint | L23: 18.16 | M23: STD20 | N23: 3105 | O23: =_xlfn.XLOOKUP(B23,Sheet1!A:A,Sheet1!E:E) -> 18.16 | P23: =_xlfn.XLOOKUP(A23,Sheet2!F:F,Sheet2!H:H) -> 529.5011 | Q23: =_xlfn.XLOOKUP(B23,April23!B:B,April23!D:D) -> 18.27 | R23: =_xlfn.XLOOKUP(B23,Sheet3!B:B,Sheet3!D:D) -> 18.82 | S23: 158 | T23: =IF(Q23>=R23,"No Change","Up") -> Up | V23: =SUM(Q23*S23) -> 2886.66 | W23: =SUM(R23*S23) -> 2973.56
A24: 5061965 | B24: 5061965 | C24: CROW01 | D24: CROWN | E24: =_xlfn.XLOOKUP(B24,Sheet1!A:A,Sheet1!B:B) -> CRT Clean Extreme | F24: =D24&" - "&E24 -> CROWN - CRT Clean Extreme | G24: =_xlfn.XLOOKUP(B24,Sheet1!A:A,Sheet1!C:C) -> White | H24: =_xlfn.XLOOKUP(B24,Sheet1!A:A,Sheet1!D:D) -> 5L | I24: Item | J24: Item | K24: Paint | L24: 24.9 | M24: STD20 | N24: 3105 | O24: =_xlfn.XLOOKUP(B24,Sheet1!A:A,Sheet1!E:E) -> 24.9 | P24: =_xlfn.XLOOKUP(A24,Sheet2!F:F,Sheet2!H:H) -> 234.39277 | Q24: =_xlfn.XLOOKUP(B24,April23!B:B,April23!D:D) -> 25.04 | R24: =Q24 -> 25.04 | S24: 152 | T24: =IF(Q24>=R24,"No Change","Up") -> No Change | V24: =SUM(Q24*S24) -> 3806.08 | W24: =SUM(R24*S24) -> 3806.08
A25: 5090804 | B25: 5090804 | C25: CROW01 | D25: CROWN | E25: =_xlfn.XLOOKUP(B25,Sheet1!A:A,Sheet1!B:B) -> CRT Fastflow Quick Dry Gloss | F25: =D25&" - "&E25 -> CROWN - CRT Fastflow Quick Dry Gloss | G25: =_xlfn.XLOOKUP(B25,Sheet1!A:A,Sheet1!C:C) -> White | H25: =_xlfn.XLOOKUP(B25,Sheet1!A:A,Sheet1!D:D) -> 5L | I25: Item | J25: Item | K25: Paint | L25: 25.8 | M25: STD20 | N25: 3105 | O25: =_xlfn.XLOOKUP(B25,Sheet1!A:A,Sheet1!E:E) -> 25.8 | P25: =_xlfn.XLOOKUP(A25,Sheet2!F:F,Sheet2!H:H) -> 290.94884 | Q25: =_xlfn.XLOOKUP(B25,April23!B:B,April23!D:D) -> 25.29 | R25: =_xlfn.XLOOKUP(B25,Sheet3!B:B,Sheet3!D:D) -> 26.05 | S25: 151 | T25: =IF(Q25>=R25,"No Change","Up") -> Up | V25: =SUM(Q25*S25) -> 3818.79 | W25: =SUM(R25*S25) -> 3933.55
A26: 6042334 | B26: 6042334 | C26: CROW01 | D26: CROWN | E26: =_xlfn.XLOOKUP(B26,Sheet1!A:A,Sheet1!B:B) -> DS PRODEC EXTRA LONG POLYESTER ROL 9IN | F26: =D26&" - "&E26 -> CROWN - DS PRODEC EXTRA LONG POLYESTER ROL 9IN | H26: Each | I26: Item | J26: Item | K26: Paint | M26: STD20 | N26: 3105 | O26: =_xlfn.XLOOKUP(B26,Sheet1!A:A,Sheet1!E:E) -> 3.24 | P26: =_xlfn.XLOOKUP(A26,Sheet2!F:F,Sheet2!H:H) -> 76.388889 | Q26: =O26*1.05 -> 3.402 | R26: 3.4 | S26: 149.91182 | T26: =IF(Q26>=R26,"No Change","Up") -> No Change | V26: =SUM(Q26*S26) -> 510 | W26: =SUM(R26*S26) -> 509.70018
A27: 5090816 | B27: 5090816 | C27: CROW01 | D27: CROWN | E27: =_xlfn.XLOOKUP(B27,Sheet1!A:A,Sheet1!B:B) -> CRT Fastflow Quick Dry Primer Undercoat | F27: =D27&" - "&E27 -> CROWN - CRT Fastflow Quick Dry Primer Undercoat | G27: =_xlfn.XLOOKUP(B27,Sheet1!A:A,Sheet1!C:C) -> White | H27: =_xlfn.XLOOKUP(B27,Sheet1!A:A,Sheet1!D:D) -> 5L | I27: Item | J27: Item | K27: Paint | L27: 25.8 | M27: STD20 | N27: 3105 | O27: =_xlfn.XLOOKUP(B27,Sheet1!A:A,Sheet1!E:E) -> 25.8 | P27: =_xlfn.XLOOKUP(A27,Sheet2!F:F,Sheet2!H:H) -> 318.7845 | Q27: =_xlfn.XLOOKUP(B27,April23!B:B,April23!D:D) -> 26 | R27: =_xlfn.XLOOKUP(B27,Sheet3!B:B,Sheet3!D:D) -> 26 | S27: 147 | T27: =IF(Q27>=R27,"No Change","Up") -> No Change | V27: =SUM(Q27*S27) -> 3822 | W27: =SUM(R27*S27) -> 3822
A28: 6055912 | B28: 6055912 | C28: CROW01 | D28: CROWN | E28: =_xlfn.XLOOKUP(B28,Sheet1!A:A,Sheet1!B:B) -> DS TRIMACO BROWN MASKING PAPER 180FT | F28: =D28&" - "&E28 -> CROWN - DS TRIMACO BROWN MASKING PAPER 180FT | H28: Each | I28: Item | J28: Item | K28: Paint | L28: 7.26 | M28: STD20 | N28: 3105 | O28: =_xlfn.XLOOKUP(B28,Sheet1!A:A,Sheet1!E:E) -> 7.26 | P28: =_xlfn.XLOOKUP(A28,Sheet2!F:F,Sheet2!H:H) -> 149.64738 | Q28: =_xlfn.XLOOKUP(B28,April23!B:B,April23!D:D) -> 5.25 | R28: =Q28*1.03 -> 5.4075 | S28: 140 | T28: =IF(Q28>=R28,"No Change","Up") -> Up | V28: =SUM(Q28*S28) -> 735 | W28: =SUM(R28*S28) -> 757.05
A29: 5024213 | B29: 5024213 | C29: CROW01 | D29: CROWN | E29: =_xlfn.XLOOKUP(B29,Sheet1!A:A,Sheet1!B:B) -> CRT Silk | F29: =D29&" - "&E29 -> CROWN - CRT Silk | G29: =_xlfn.XLOOKUP(B29,Sheet1!A:A,Sheet1!C:C) -> Magnolia | H29: =_xlfn.XLOOKUP(B29,Sheet1!A:A,Sheet1!D:D) -> 10L | I29: Item | J29: Item | K29: Paint | L29: 26.29 | M29: STD20 | N29: 3105 | O29: =_xlfn.XLOOKUP(B29,Sheet1!A:A,Sheet1!E:E) -> 26.29 | P29: =_xlfn.XLOOKUP(A29,Sheet2!F:F,Sheet2!H:H) -> 1081.8414 | Q29: =_xlfn.XLOOKUP(B29,April23!B:B,April23!D:D) -> 28.09 | R29: =_xlfn.XLOOKUP(B29,Sheet3!B:B,Sheet3!D:D) -> 28.09 | S29: 138 | T29: =IF(Q29>=R29,"No Change","Up") -> No Change | V29: =SUM(Q29*S29) -> 3876.42 | W29: =SUM(R29*S29) -> 3876.42
A30: 5064671 | B30: 5064671 | C30: CROW01 | D30: CROWN | E30: =_xlfn.XLOOKUP(B30,Sheet1!A:A,Sheet1!B:B) -> CRT Acrylic Eggshell | F30: =D30&" - "&E30 -> CROWN - CRT Acrylic Eggshell | G30: =_xlfn.XLOOKUP(B30,Sheet1!A:A,Sheet1!C:C) -> Magnolia | H30: =_xlfn.XLOOKUP(B30,Sheet1!A:A,Sheet1!D:D) -> 5L | I30: Item | J30: Item | K30: Paint | L30: 21.01 | M30: STD20 | N30: 3105 | O30: =_xlfn.XLOOKUP(B30,Sheet1!A:A,Sheet1!E:E) -> 21.01 | P30: =_xlfn.XLOOKUP(A30,Sheet2!F:F,Sheet2!H:H) -> 307.99714 | Q30: =_xlfn.XLOOKUP(B30,April23!B:B,April23!D:D) -> 26.14 | R30: =Q30 -> 26.14 | S30: 135 | T30: =IF(Q30>=R30,"No Change","Up") -> No Change | V30: =SUM(Q30*S30) -> 3528.9 | W30: =SUM(R30*S30) -> 3528.9
A31: 6055707 | B31: 6055707 | C31: CROW01 | D31: CROWN | E31: =_xlfn.XLOOKUP(B31,Sheet1!A:A,Sheet1!B:B) -> DS OAKEY FLEXIBLE FINISH PADS EX MED/CRS | F31: =D31&" - "&E31 -> CROWN - DS OAKEY FLEXIBLE FINISH PADS EX MED/CRS | H31: Each | I31: Item | J31: Item | K31: Paint | L31: 1.06 | M31: STD20 | N31: 3105 | O31: =_xlfn.XLOOKUP(B31,Sheet1!A:A,Sheet1!E:E) -> 1.06 | P31: =_xlfn.XLOOKUP(A31,Sheet2!F:F,Sheet2!H:H) -> 0 | Q31: =_xlfn.XLOOKUP(B31,April23!B:B,April23!D:D) -> 1.11 | R31: 1.11 | S31: 133 | T31: =IF(Q31>=R31,"No Change","Up") -> No Change | V31: =SUM(Q31*S31) -> 147.63 | W31: =SUM(R31*S31) -> 147.63
A32: 5093395 | B32: 5093395 | C32: CROW01 | D32: CROWN | E32: =_xlfn.XLOOKUP(B32,Sheet1!A:A,Sheet1!B:B) -> CRT Clean Extreme Mould Inhibiting Matt | F32: =D32&" - "&E32 -> CROWN - CRT Clean Extreme Mould Inhibiting Matt | G32: =_xlfn.XLOOKUP(B32,Sheet1!A:A,Sheet1!C:C) -> White | H32: =_xlfn.XLOOKUP(B32,Sheet1!A:A,Sheet1!D:D) -> 5L | I32: Item | J32: Item | K32: Paint | L32: 38.03 | M32: STD20 | N32: 3105 | O32: =_xlfn.XLOOKUP(B32,Sheet1!A:A,Sheet1!E:E) -> 38.03 | P32: =_xlfn.XLOOKUP(A32,Sheet2!F:F,Sheet2!H:H) -> 307.39968 | Q32: =_xlfn.XLOOKUP(B32,April23!B:B,April23!D:D) -> 33.87 | R32: =_xlfn.XLOOKUP(B32,Sheet3!B:B,Sheet3!D:D) -> 33.87 | S32: 125 | T32: =IF(Q32>=R32,"No Change","Up") -> No Change | V32: =SUM(Q32*S32) -> 4233.75 | W32: =SUM(R32*S32) -> 4233.75
A33: 5091987 | B33: 5091987 | C33: CROW01 | D33: CROWN | E33: =_xlfn.XLOOKUP(B33,Sheet1!A:A,Sheet1!B:B) -> CRT Fastflow QD Satin | F33: =D33&" - "&E33 -> CROWN - CRT Fastflow QD Satin | G33: =_xlfn.XLOOKUP(B33,Sheet1!A:A,Sheet1!C:C) -> White | H33: =_xlfn.XLOOKUP(B33,Sheet1!A:A,Sheet1!D:D) -> 5L | I33: Item | J33: Item | K33: Paint | L33: 30.77 | M33: STD20 | N33: 3105 | O33: =_xlfn.XLOOKUP(B33,Sheet1!A:A,Sheet1!E:E) -> 30.77 | P33: =_xlfn.XLOOKUP(A33,Sheet2!F:F,Sheet2!H:H) -> 282.51934 | Q33: =_xlfn.XLOOKUP(B33,April23!B:B,April23!D:D) -> 28 | R33: =_xlfn.XLOOKUP(B33,Sheet3!B:B,Sheet3!D:D) -> 28 | S33: 122 | T33: =IF(Q33>=R33,"No Change","Up") -> No Change | V33: =SUM(Q33*S33) -> 3416 | W33: =SUM(R33*S33) -> 3416
A34: 6061964 | B34: 6061964 | C34: CROW01 | D34: CROWN | E34: =_xlfn.XLOOKUP(B34,Sheet1!A:A,Sheet1!B:B) -> DS HAMILTON MEDIUM PILE ROLLER 4IN 10PK | F34: =D34&" - "&E34 -> CROWN - DS HAMILTON MEDIUM PILE ROLLER 4IN 10PK | H34: Each | I34: Item | J34: Item | K34: Paint | M34: STD20 | N34: 3105 | O34: =_xlfn.XLOOKUP(B34,Sheet1!A:A,Sheet1!E:E) -> 3.9 | P34: =_xlfn.XLOOKUP(A34,Sheet2!F:F,Sheet2!H:H) -> 109.17949 | Q34: =O34*1.05 -> 4.095 | R34: 4.1 | S34: 119.1453 | T34: =IF(Q34>=R34,"No Change","Up") -> Up | V34: =SUM(Q34*S34) -> 487.9 | W34: =SUM(R34*S34) -> 488.49573
A35: 5026990 | B35: 5026990 | C35: CROW01 | D35: CROWN | E35: =_xlfn.XLOOKUP(B35,Sheet1!A:A,Sheet1!B:B) -> CRT Solvent-borne Full Gloss | F35: =D35&" - "&E35 -> CROWN - CRT Solvent-borne Full Gloss | G35: =_xlfn.XLOOKUP(B35,Sheet1!A:A,Sheet1!C:C) -> Brilliant White | H35: =_xlfn.XLOOKUP(B35,Sheet1!A:A,Sheet1!D:D) -> 5L | I35: Item | J35: Item | K35: Paint | L35: 16.32 | M35: STD20 | N35: 3105 | O35: =_xlfn.XLOOKUP(B35,Sheet1!A:A,Sheet1!E:E) -> 16.32 | P35: =_xlfn.XLOOKUP(A35,Sheet2!F:F,Sheet2!H:H) -> 62.909926 | Q35: =_xlfn.XLOOKUP(B35,April23!B:B,April23!D:D) -> 19.68 | R35: =_xlfn.XLOOKUP(B35,Sheet3!B:B,Sheet3!D:D) -> 20.27 | S35: 118 | T35: =IF(Q35>=R35,"No Change","Up") -> Up | V35: =SUM(Q35*S35) -> 2322.24 | W35: =SUM(R35*S35) -> 2391.86
A36: 6040483 | B36: 6040483 | C36: CROW01 | D36: CROWN | E36: =_xlfn.XLOOKUP(B36,Sheet1!A:A,Sheet1!B:B) -> WA AS CREATION CASABLANCA 4 WALL | F36: =D36&" - "&E36 -> CROWN - WA AS CREATION CASABLANCA 4 WALL | H36: Each | I36: Item | J36: Item | K36: Paint | M36: STD20 | N36: 3105 | O36: =_xlfn.XLOOKUP(B36,Sheet1!A:A,Sheet1!E:E) -> 5 | P36: =_xlfn.XLOOKUP(A36,Sheet2!F:F,Sheet2!H:H) -> 1186.608 | Q36: =O36*1.05 -> 5.25 | R36: =Q36*1.03 -> 5.4075 | S36: 117.71429 | T36: =IF(Q36>=R36,"No Change","Up") -> Up | V36: =SUM(Q36*S36) -> 618 | W36: =SUM(R36*S36) -> 636.54
A37: 5073961 | B37: 5073961 | C37: CROW01 | D37: CROWN | E37: =_xlfn.XLOOKUP(B37,Sheet1!A:A,Sheet1!B:B) -> ST RUST INHIB PRIMER GREY 2.5L | F37: =D37&" - "&E37 -> CROWN - ST RUST INHIB PRIMER GREY 2.5L | H37: 5L | I37: Item | J37: Item | K37: Paint | L37: 43.03 | M37: STD20 | N37: 3105 | O37: =_xlfn.XLOOKUP(B37,Sheet1!A:A,Sheet1!E:E) -> 43.03 | P37: =_xlfn.XLOOKUP(A37,Sheet2!F:F,Sheet2!H:H) -> 0 | Q37: =O37*1.03 -> 44.3209 | R37: 40 | S37: 112.99771 | T37: Down | V37: =SUM(Q37*S37) -> 5008.16 | W37: =SUM(R37*S37) -> 4519.9082
A38: 6040125 | B38: 6040125 | C38: CROW01 | D38: CROWN | E38: =_xlfn.XLOOKUP(B38,Sheet1!A:A,Sheet1!B:B) -> WA ANAGLYPTA TEXT VINYL WILL BO RD804301 | F38: =D38&" - "&E38 -> CROWN - WA ANAGLYPTA TEXT VINYL WILL BO RD804301 | H38: Each | I38: Item | J38: Item | K38: Paint | L38: 4.8 | M38: STD20 | N38: 3105 | O38: =_xlfn.XLOOKUP(B38,Sheet1!A:A,Sheet1!E:E) -> 4.8 | P38: =_xlfn.XLOOKUP(A38,Sheet2!F:F,Sheet2!H:H) -> 2858.4188 | Q38: =_xlfn.XLOOKUP(B38,April23!B:B,April23!D:D) -> 4.94 | R38: =Q38*1.03 -> 5.0882 | S38: 107 | T38: =IF(Q38>=R38,"No Change","Up") -> Up | V38: =SUM(Q38*S38) -> 528.58 | W38: =SUM(R38*S38) -> 544.4374
A39: 6055201 | B39: 6055201 | C39: CROW01 | D39: CROWN | E39: =_xlfn.XLOOKUP(B39,Sheet1!A:A,Sheet1!B:B) -> DE ESS PAINT BRUSH 2IN(12) EACH | F39: =D39&" - "&E39 -> CROWN - DE ESS PAINT BRUSH 2IN(12) EACH | H39: Each | I39: Item | J39: Item | K39: Paint | L39: 1.38 | M39: STD20 | N39: 3105 | O39: =_xlfn.XLOOKUP(B39,Sheet1!A:A,Sheet1!E:E) -> 1.38 | P39: =_xlfn.XLOOKUP(A39,Sheet2!F:F,Sheet2!H:H) -> 563.89855 | Q39: =_xlfn.XLOOKUP(B39,April23!B:B,April23!D:D) -> 1.42 | R39: =_xlfn.XLOOKUP(B39,Sheet4!B:B,Sheet4!D:D) -> 1.42 | S39: 103 | T39: =IF(Q39>=R39,"No Change","Up") -> No Change | V39: =SUM(Q39*S39) -> 146.26 | W39: =SUM(R39*S39) -> 146.26
A40: 6062917 | B40: 6062917 | C40: CROW01 | D40: CROWN | E40: =_xlfn.XLOOKUP(B40,Sheet1!A:A,Sheet1!B:B) -> WA FINE DECOR CONTRACTOR BOOK 23 A | F40: =D40&" - "&E40 -> CROWN - WA FINE DECOR CONTRACTOR BOOK 23 A | H40: Each | I40: Item | J40: Item | K40: Paint | M40: STD20 | N40: 3105 | O40: =_xlfn.XLOOKUP(B40,Sheet1!A:A,Sheet1!E:E) -> 10 | P40: =_xlfn.XLOOKUP(A40,Sheet2!F:F,Sheet2!H:H) -> 36 | Q40: =O40*1.05 -> 10.5 | R40: =Q40*1.03 -> 10.815 | S40: 102.85714 | T40: =IF(Q40>=R40,"No Change","Up") -> Up | V40: =SUM(Q40*S40) -> 1080 | W40: =SUM(R40*S40) -> 1112.4
...

Sheet Sheet7
B1: REF:AC/CRT-TRC/22.05.23/V03
B2: Account Name | D2: Bell Group
B3: Payer Account Number | D3: 12973
B4: or
B5: Price Group
B6: Promotion Code (if applicable)
B7: Start Date
B8: End Date
B9: Authorised By | D9: Ayer/Nigel/Waqas
B10: Date Authorised | D10: 45496
B11: Maintained By (Pricing Dept)
B12: Date Maintained
A15: SAP number | B15: Material description | C15: Colour | D15: Size | E15: Load | F15: Price | H15: 6063177 | I15: DS BARTOLINE 1876 AP ADHESIVE 30 ROLL | J15: 4.38 | L15: 5091202 | M15: ST FLEXIGLOSS XTRA BASE PLATNUM LT 2.5L | N15: 25.93
A16: 5064671 | B16: CRT ACRYLIC EGGSHELL | C16: MAGNOLIA | D16: 5000 | E16: 5064671 | F16: 26.14 | H16: 6048207 | I16: DS REPAIR CARE DRY FLEX 4 | J16: 56.7 | L16: 5091203 | M16: ST FLEXIGLOSS XTRA BASE OPAL MID 2.5L | N16: 25.93
A17: 5024173 | B17: CRT ACRYLIC PRIMER UNDERCOAT | C17: WHITE | D17: 2500 | E17: 5024173 | F17: 14.38 | H17: 6041658 | I17: DS PRODEC REFUSE SACKS 50 ROLL | J17: 8.3055 | L17: 5091204 | M17: ST FLEXIGLOSS XTRA BASE CRYSTAL DK 2.5L | N17: 25.93
A18: 5027073 | B18: CRT ALL PURP PRIMER PX3 | C18: OFF WHITE | D18: 5000 | E18: 5027073 | F18: 25.12 | H18: 6048367 | I18: DS ZINSSER DIF WALLPAPER STRIPPER 1L | J18: 10.76 | L18: 5041062 | M18: ST FLEXIGLOSS X-TRA BRIL WHITE 1L | N18: 10.49
A19: 5094753 | B19: CRT ALL PURP PRIMER PX4 | C19: WHITE | D19: 5000 | E19: 5094753 | F19: 35.56 | H19: 6062944 | I19: DS Q1 CONTRACTOR MASKING TAPE 50M 48MM | J19: 2.1 | L19: 5041097 | M19: ST FLEXIGLOSS X-TRA BRIL WHITE 2.5L | N19: 21.5
A20: 5088598 | B20: CRT CLEAN EXTREME A-BAC SCRUBBABLE MATT | C20: WHITE | D20: 5000 | E20: 5088598 | F20: 35.05 | H20: 6061964 | I20: DS HAMILTON MEDIUM PILE ROLLER 4IN 10PK | J20: 4.1 | L20: 5041116 | M20: ST FLEXIGLOSS X-TRA BRIL WHITE 5L | N20: 43
A21: 5088591 | B21: CRT CLEAN EXTREME ACRYLIC EGGSHELL | C21: WHITE | D21: 5000 | E21: 5088591 | F21: 29.76 | H21: 6060622 | I21: DS ULTRAGRIME PRO POWER SCRUB XXL+ 80PK | J21: 15 | L21: 5089340 | M21: ST METAL GLOSS X-TRA BLACK 2.5L | N21: 25.93
A22: 5061965 | B22: CRT CLEAN EXTREME SCRUBBABLE MATT | C22: WHITE | D22: 5000 | E22: 5061965 | F22: 25.04 | H22: 6062122 | I22: DS HIPPO MP BAMBOO DRY CLOTH 60 SHEETS | J22: 10.82 | L22: 5089400 | M22: ST METAL GLOSS X-TRA WHITE 2.5L | N22: 30.86
A23: 5061839 | B23: CRT CLEAN EXTREME SCRUBBABLE MATT | C23: MAGNOLIA | D23: 5000 | E23: 5061839 | F23: 25.97 | H23: 6055142 | I23: DS ULTRAGRIME PRO XXL+MULTI WIPES 100PK | J23: 13.5 | L23: 5025656 | M23: ST FINE TEXT MATT BLACK 5L | N23: 22.22
A24: 5023890 | B24: CRT COVERMATT EMULSION | C24: WHITE | D24: 5000 | E24: 5023890 | F24: 11.45 | H24: 6058266 | I24: DS FLUXAF POWER CLEAN 750ML | J24: 7.98 | L24: 5025660 | M24: ST FINE TEXT MATT BRIL WHITE 5L | N24: 20.98
A25: 5023888 | B25: CRT COVERMATT EMULSION | C25: MAGNOLIA | D25: 10000 | E25: 5023888 | F25: 23.44 | H25: 6055424 | I25: DE PROFESSIONAL MEDUIM GPUR ROLLER 4IN | J25: 0.39 | L25: 5091199 | M25: ST FINE TEXT MATT BASE PLATNUM LT 5L | N25: 19.75
A26: 5027038 | B26: CRT EGGSHELL | C26: WHITE | D26: 5000 | E26: 5027038 | F26: 22.72 | H26: 6041133 | I26: DS INDASA MTE MASKING TAPE 48MM | J26: 3.3 | L26: 5091200 | M26: ST FINE TEXT MATT BASE OPAL MID 5L | N26: 19.75
A27: 5090805 | B27: CRT FASTFLOW QUICK DRY GLOSS | C27: BLACK | D27: 2500 | E27: 5090805 | F27: 16.13 | H27: 6061968 | I27: DS HAMILTON LONG PILE ROLLER 9IN | J27: 3.32
A28: 5090815 | B28: CRT FASTFLOW QUICK DRY PRIMER UNDERCOAT | C28: WHITE | D28: 2500 | E28: 5090815 | F28: 14.01 | H28: 6042334 | I28: DS PRODEC EXTRA LONG POLYESTER ROL 9IN | J28: 3.4
A29: 5093360 | B29: CRT FASTFLOW QUICK DRY PR U/COAT (FQU) | C29: COLOUR | D29: 2500 | E29: CRTFQUCOL2500 | F29: 16.13 | H29: 6042088 | I29: DS PERFECTION ROLLER MEDIUM 9IN | J29: 3.75
A30: 5092766 | B30: TRC FASTFLOW PRIMER U/COAT (FQU) | C30: COLOUR | D30: 2500 | E30: TRCFQUCOL2500 | F30: 16.13 | H30: 6042089 | I30: DS PERFECTION ROLLER LONG 9IN | J30: 4.5
A31: 5092691 | B31: TRC FASTFLOW PRIMER U/COAT | C31: BASE | D31: 2500 | E31: TRCFQUBAS2500 | F31: 16.13 | H31: 6042090 | I31: DS PERFECTION ROLLER X LONG 9IN | J31: 5.75
A32: 5091986 | B32: CRT FASTFLOW QUICK DRY SATIN | C32: WHITE | D32: 2500 | E32: 5091986 | F32: 16.72 | H32: 6042877 | I32: DS CIRET BAG OF RAGS COLOURED 10K | J32: 33.09
A33: 5024071 | B33: CRT MATT EMULSION | C33: BWT | D33: 5000 | E33: 5024071 | F33: 14.17 | H33: 6053484 | I33: DS BLACKROCK PAINTERS LW GRIPPER GLOVE | J33: 1.659
A34: 5024051 | B34: CRT MATT EMULSION | C34: MAGNOLIA | D34: 5000 | E34: 5024051 | F34: 14.02 | H34: 6055707 | I34: DS OAKEY FLEXIBLE FINISH PADS EX MED/CRS | J34: 1.11
A35: 5090088 | B35: CRT PRO-CO FD CLADDING FINISH | C35: WHITE | D35: 5000 | E35: 5090088 | F35: 44 | H35: 6042110 | I35: DS PRESTIGE CAGE FRAME 9IN | J35: 5.75
A36: 5089389 | B36: CRT PRO-CO HP GLOSS | C36: WHITE | D36: 2500 | E36: 5089389 | F36: 26.14 | H36: 6042316 | I36: DS BLACKROCK PAINTERS L/W GRIPPER GLOVES | J36: 3.41
A37: 5074313 | B37: CRT SATIN | C37: WHITE | D37: 5000 | E37: 5074313 | F37: 26.39 | H37: 5073961 | I37: ST RUST INHIB PRIMER GREY 2.5L | J37: 40
A38: 5074312 | B38: CRT SATIN | C38: WHITE | D38: 2500 | E38: 5074312 | F38: 15.44 | H38: 5028216 | I38: ST 365 SMOOTH BRIL WHITE 5L | J38: 35
A39: 5024027 | B39: CRT STRONGHOLD SMOOTH | C39: WHITE | D39: 10000 | E39: 5024027 | F39: 42.72
A41: Comments

Sheet Sheet6
A1: Product | C1: Sales Volume | D1: Sales Value | E1: Gross Margin | F1: ASP
A2: 5023891 | B2: CT COVERMATT WHITE 10L | C2: 18420 | D2: 43765.92 | E2: 27065.13 | F2: 2.376
A3: 5090984 | B3: CT ACR EGG TIMONOX BASE PLATNUM LT 5L | C3: 3300 | D3: 31680 | E3: 11942.59 | F3: 9.6
A4: 5040579 | B4: CT MATT EMUL TIMONOX BRIL WHITE 5L | C4: 3045 | D4: 25042.08 | E4: 14779.6 | F4: 8.224
A5: 5091032 | B5: CT MATT TIMONOX BASE PLATNUM LT 5L | C5: 1745 | D5: 15007 | E5: 8968.75 | F5: 8.6
A6: 6046432 | B6: WA ANAGLYPTA PRECISION ROYAL OAK RD7000 | C6: 0 | D6: 12392.72 | E6: 6802.09 | F6: 0
A7: 5090989 | B7: CT ACR EGGSHELL BASE PLATNUM LT 5L | C7: 2980 | D7: 12039.2 | E7: 6463.31 | F7: 4.04
A8: 5090996 | B8: CT CLNEX SR SC MATT BSE PLATNUM LT 5L | C8: 1920 | D8: 11500.8 | E8: 7072.71 | F8: 5.99
A9: 5026956 | B9: CT FULL GLOSS WHITE 5L | C9: 2170 | D9: 11162.48 | E9: 4038.2 | F9: 5.144
A10: 5024010 | B10: CT STRONGHOLD SMOOTH MAGNOLIA 5L | C10: 2700 | D10: 10972.8 | E10: 5507.76 | F10: 4.064
A11: 6058266 | B11: DS FLUXAF POWER CLEAN 750ML | C11: 0 | D11: 9583.98 | E11: 5392.49 | F11: 0
A12: 5088437 | B12: CT SHED&FENCE OPAQUE DARK BROWN 5L | C12: 2775 | D12: 9146.4 | E12: 3661.44 | F12: 3.296
A13: 5091086 | B13: CT TIMONOX SC MATT BASE PLATNUM LT 5L | C13: 725 | D13: 8202.65 | E13: 3854.1 | F13: 11.314
... A1593: 5023901 | B1593: CT COVERMATT SOFT WHITE 10L | C1593: -10 | D1593: -23.44 | E1593: -12.37 | F1593: 2.344
A1594: Total | C1594: 87182 | D1594: 523208.82 | E1594: 273508.99 | F1594: 6.00134

Sheet Sheet3
A1: Cust_No. | B1: SAP_Number | C1: Matl_Desc. | D1: Price | E1: Desc. | F1: Size | G1: Unit | H1: Date | I1: EAN-code | J1: Currency
A2: 12973 | B2: 5092337 | C2: MC ECLIPSE EMULSION TINT COL 10L | D2: 21.76 | E2: MC ECLIPSE EMULSION IDS COL | F2: 1 | G2: PC | H2: 45505 | J2: GBP
A3: 12973 | B3: 5092338 | C3: MC ECLIPSE EMULSION TINT COL 5L | D3: 11 | E3: MC ECLIPSE EMULSION IDS COL | F3: 1 | G3: PC | H3: 45505 | J3: GBP
A4: 12973 | B4: 5101250 | C4: MC QUICK DRY EGGSHELL BRIL WHITE 2.5L | D4: 12 | E4: MAC Quick Dry Eggshell BWT | F4: 1 | G4: PC | H4: 45505 | I4: 5010131585517 | J4: GBP
A5: 12973 | B5: 5101270 | C5: MC QUICK DRY EGGSHELL BLACK 2.5L | D5: 12.8 | E5: MAC Quick Dry Eggshell COL | F5: 1 | G5: PC | H5: 45505 | I5: 5010131585630 | J5: GBP
A6: 12973 | B6: 5101249 | C6: MC QUICK DRY GLOSS BRIL WHITE 1L | D6: 6.4 | E6: MAC Quick Dry Gloss BWT | F6: 1 | G6: PC | H6: 45505 | I6: 5010131585500 | J6: GBP
A7: 12973 | B7: 5101271 | C7: MC QUICK DRY GLOSS BRIL WHITE 5L | D7: 24.8 | E7: MAC Quick Dry Gloss BWT | F7: 1 | G7: PC | H7: 45505 | I7: 5010131585654 | J7: GBP
A8: 12973 | B8: 5101272 | C8: MC QUICK DRY GLOSS BLACK 2.5L | D8: 15.2 | E8: MAC Quick Dry Gloss COL | F8: 1 | G8: PC | H8: 45505 | I8: 5010131585661 | J8: GBP
A9: 12973 | B9: 5101276 | C9: MC QUICK DRY SATIN BRIL WHITE 5L | D9: 24.8 | E9: MAC Quick Dry Satin BWT | F9: 1 | G9: PC | H9: 45505 | I9: 5010131585715 | J9: GBP
A10: 12973 | B10: 5101252 | C10: MC QUICK DRY SATIN BRIL WHITE 2.5L | D10: 12.8 | E10: MAC Quick Dry Satin BWT | F10: 1 | G10: PC | H10: 45505 | I10: 5010131585531 | J10: GBP
A11: 12973 | B11: 5101251 | C11: MC QUICK DRY SATIN BRIL WHITE 1L | D11: 7.2 | E11: MAC Quick Dry Satin BWT | F11: 1 | G11: PC | H11: 45505 | I11: 5010131585524 | J11: GBP
A12: 12973 | B12: 5101277 | C12: MC QUICK DRY SATIN BLACK 2.5L | D12: 15.2 | E12: MAC Quick Dry Satin COL | F12: 1 | G12: PC | H12: 45505 | I12: 5010131585722 | J12: GBP
A13: 12973 | B13: 5092359 | C13: MC VINYL MATT EMULSION TINT COL 10L | D13: 27.75 | E13: MC VINYL MATT EMULSION IDS COL | F13: 1 | G13: PC | H13: 45505 | J13: GBP
A14: 12973 | B14: 5092358 | C14: MC VINYL MATT EMULSION TINT COL 5L | D14: 14.31 | E14: MC VINYL MATT EMULSION IDS COL | F14: 1 | G14: PC | H14: 45505 | J14: GBP
A15: 12973 | B15: 5092357 | C15: MC VINYL MATT EMULSION TINT COL 2.5L | D15: 9.63 | E15: MC VINYL MATT EMULSION IDS COL | F15: 1 | G15: PC | H15: 45505 | J15: GBP
A16: 12973 | B16: 5091756 | C16: MC MID SHEEN EMUL MC1 TINTED 5L | D16: 17.92 | E16: MC MID SHEEN EMULSION IDS COL | F16: 1 | G16: PC | H16: 45505 | J16: GBP
A17: 12973 | B17: 5091755 | C17: MC MID SHEEN EMUL MC1 TINTED 2.5L | D17: 11.43 | E17: MC MID SHEEN EMULSION IDS COL | F17: 1 | G17: PC | H17: 45505 | J17: GBP
A18: 12973 | B18: 5091754 | C18: MC MID SHEEN EMUL MC1 TINTED 10L | D18: 25.92 | E18: MC MID SHEEN EMULSION IDS COL | F18: 1 | G18: PC | H18: 45505 | J18: GBP
A19: 12973 | B19: 5091753 | C19: MC MID SHEEN EMUL MC2 TINTED 5L | D19: 17.92 | E19: MC MID SHEEN EMULSION IDS COL | F19: 1 | G19: PC | H19: 45505 | J19: GBP
A20: 12973 | B20: 5091752 | C20: MC MID SHEEN EMUL MC2 TINTED 2.5L | D20: 11.43 | E20: MC MID SHEEN EMULSION IDS COL | F20: 1 | G20: PC | H20: 45505 | J20: GBP
A21: 12973 | B21: 5091751 | C21: MC MID SHEEN EMUL MC3 TINTED 5L | D21: 17.92 | E21: MC MID SHEEN EMULSION IDS COL | F21: 1 | G21: PC | H21: 45505 | J21: GBP
A22: 12973 | B22: 5091750 | C22: MC MID SHEEN EMUL MC3 TINTED 2.5L | D22: 11.43 | E22: MC MID SHEEN EMULSION IDS COL | F22: 1 | G22: PC | H22: 45505 | J22: GBP
A23: 12973 | B23: 5092342 | C23: MC GLOSS TINT COL 1L | D23: 6.25 | E23: MC GLOSS IDS COL | F23: 1 | G23: PC | H23: 45505 | J23: GBP
A24: 12973 | B24: 5092336 | C24: MC ACRYLIC EGGSHELL TINT COL 5L | D24: 23.07 | E24: MC ACRYLIC EGGSHELL IDS COL | F24: 1 | G24: PC | H24: 45505 | J24: GBP
A25: 12973 | B25: 5088591 | C25: CT CLNEX SR AC EGG WHITE 5L | D25: 30.65 | E25: CRT Clean Extreme Acr Egg White | F25: 1 | G25: PC | H25: 45505 | I25: 5010131525407 | J25: GBP
A26: 12973 | B26: 5088704 | C26: CT CLN EXTREME ACR EGG 5L | D26: 35.83 | E26: CRT Clean Extreme Acr Egg Col | F26: 1 | G26: PC | H26: 45505 | I26: 5010131575341 | J26: GBP
A27: 12973 | B27: 5088596 | C27: CT CLNEX AB AC EGG WHITE 5L | D27: 36.1 | E27: CRT Steracryl A/Bac Acr Egg White | F27: 1 | G27: PC | H27: 45505 | I27: 5010131525452 | J27: GBP
A28: 12973 | B28: 5088693 | C28: CT CLNEX A/BAC ACR EGG 5L | D28: 44.92 | E28: CRT Steracryl A/Bac Acr Egg Col | F28: 1 | G28: PC | H28: 45505 | I28: 5010131575372 | J28: GBP
A29: 12973 | B29: 5090513 | C29: CT CLNEX MI AC EGGSHELL WHITE 2.5L | D29: 17.31 | E29: CRT Steracryl M/Inhibit Acr Egg White | F29: 1 | G29: PC | H29: 45505 | I29: 5010131548789 | J29: GBP
A30: 12973 | B30: 5088594 | C30: CT CLNEX MI AC EGGSHELL WHITE 5L | D30: 35.41 | E30: CRT Steracryl M/Inhibit Acr Egg White | F30: 1 | G30: PC | H30: 45505 | I30: 5010131525438 | J30: GBP
A31: 12973 | B31: 5088695 | C31: CT CLNEX M INH ACR EGG 5L | D31: 39.74 | E31: CRT Steracryl M/Inhibit Acr Egg Col | F31: 1 | G31: PC | H31: 45505 | I31: 5010131575396 | J31: GBP
A32: 12973 | B32: 5091934 | C32: CT CLNEX M INH ACR EGG 2.5L | D32: 21.53 | E32: CRT Steracryl M/Inhibit Acr Egg Col | F32: 1 | G32: PC | H32: 45505 | I32: 5010131575402 | J32: GBP
A33: 12973 | B33: 5064685 | C33: CT ACRYLIC EGGSHELL WHITE 2.5L | D33: 14.69 | E33: CRT Best Fin Acrylic Eggshell White | F33: 1 | G33: PC | H33: 45505 | I33: 5010131494567 | J33: GBP
A34: 12973 | B34: 5064686 | C34: CT ACRYLIC EGGSHELL WHITE 5L | D34: 17.4 | E34: CRT Best Fin Acrylic Eggshell White | F34: 1 | G34: PC | H34: 45505 | I34: 5010131494574 | J34: GBP
A35: 12973 | B35: 5097347 | C35: CT ACRYLIC EGGSHELL WHITE 10L | D35: 33 | E35: CRT Best Fin Acrylic Eggshell White | F35: 1 | G35: PC | H35: 45505 | I35: 5010131584220 | J35: GBP
A36: 12973 | B36: 5064671 | C36: CT ACRYLIC EGGSHELL MAGNOLIA 5L | D36: 26.92 | E36: CRT Best Fin Acrylic Eggshell Magnolia | F36: 1 | G36: PC | H36: 45505 | I36: 5010131494413 | J36: GBP
... A72: 12973 | B72: 5093674 | C72: CT FASTFLOW QD EGGSHELL WHITE 2.5L | D72: 18.94 | E72: CRT Fastflow Quick Dry Eggshell White | F72: 1 | G72: PC | H72: 45505 | I72: 5010131576942 | J72: GBP
A73: 12973 | B73: 5095633 | C73: CT FASTFLOW QD EGGSHELL 2.5L | D73: 25.36 | E73: CT FF QD Eggshell Base COL | F73: 1 | G73: PC | H73: 45505 | J73: GBP
A74: 12973 | B74: 5095632 | C74: CT FASTFLOW QD EGGSHELL 1L | D74: 11.58 | E74: CT FF QD Eggshell Base COL | F74: 1 | G74: PC | H74: 45505 | J74: GBP
A75: 12973 | B75: 5090805 | C75: CT FASTFLOW QD GLOSS BLACK 2.5L | D75: 16.61 | E75: CRT Fastflow Quick Dry Gloss Black | F75: 1 | G75: PC | H75: 45505 | I75: 5010131552809 | J75: GBP
...

Sheet Sheet4
A1: Cust_No. | B1: SAP_Number | C1: Matl_Desc. | D1: Price | E1: Desc. | F1: Size | G1: Unit | H1: Date | I1: EAN-code | J1: Currency
A2: 12973 | B2: 6055954 | C2: DS OAKEY BTW CTS FINISH PAPER 240G 5M | D2: 8.24 | E2: BDS Abrasives | F2: 1 | G2: PC | H2: 45505 | I2: 3157629665138 | J2: GBP
A3: 12973 | B3: 6055709 | C3: DS OAKEY FLEX FINISH PAD EX FINE/FINE | D3: 1.14 | E3: BDS Abrasives | F3: 1 | G3: PC | H3: 45505 | I3: 3157629794685 | J3: GBP
A4: 12973 | B4: 6055707 | C4: DS OAKEY FLEXIBLE FINISH PADS EX MED/CRS | D4: 1.14 | E4: BDS Abrasives | F4: 1 | G4: PC | H4: 45505 | I4: 3157629794678 | J4: GBP
A5: 12973 | B5: 6053563 | C5: DS INDASA ABRASIVE BLOCK P100 1PC | D5: 1.03 | E5: BDS Abrasives | F5: 1 | G5: PC | H5: 45505 | I5: 5603902463000 | J5: GBP
A6: 12973 | B6: 6053562 | C6: DS INDASA RHYNALOX PLUSLINE ASSRTD 10PK | D6: 6.7 | E6: BDS Abrasives | F6: 1 | G6: PC | H6: 45505 | I6: 5603902583708 | J6: GBP
A7: 12973 | B7: 6053561 | C7: DS INDASA RHYNOWOOD ASSORTED 5PK | D7: 2.32 | E7: BDS Abrasives | F7: 1 | G7: PC | H7: 45505 | I7: 5603902583715 | J7: GBP
A8: 12973 | B8: 6053560 | C8: DS INDASA RHYNOWET W LINE ASSRTD 4PK | D8: 2.83 | E8: BDS Abrasives | F8: 1 | G8: PC | H8: 45505 | I8: 5603902583692 | J8: GBP
A9: 12973 | B9: 6047323 | C9: DS INDASA SPONGE PADS P120 10PK | D9: 5.67 | E9: BDS Abrasives | F9: 1 | G9: PC | H9: 45505 | I9: 5603902014493 | J9: GBP
A10: 12973 | B10: 6047322 | C10: DS INDASA SPONGE PADS P100 10PK | D10: 5.67 | E10: BDS Abrasives | F10: 1 | G10: PC | H10: 45505 | I10: 5603902014486 | J10: GBP
A11: 12973 | B11: 6047321 | C11: DS INDASA SPONGE PADS P80 10PK | D11: 5.67 | E11: BDS Abrasives | F11: 1 | G11: PC | H11: 45505 | I11: 5603902476314 | J11: GBP
A12: 12973 | B12: 6047320 | C12: DS INDASA SPONGE PADS P60 10PK | D12: 5.67 | E12: BDS Abrasives | F12: 1 | G12: PC | H12: 45505 | I12: 5603902014479 | J12: GBP
A13: 12973 | B13: 6046792 | C13: DS INDASA RHYNALOX PLUS P80 115MM 10M | D13: 9.27 | E13: BDS Abrasives | F13: 1 | G13: PC | H13: 45505 | I13: 5603902498637 | J13: GBP
... A513: 12973 | B513: 5091199 | C513: ST FINE TEXT MATT BASE PLATNUM LT 5L | D513: 26.62 | E513: ST FINE TEXT MATT BASE PLATINUM | F513: 1 | G513: PC | H513: 45505 | I513: 5010131556906 | J513: GBP
A514: 6041137 - DS INDASA RHYNOLITE YEL 60G 115MMX10M | B514: 0 | C514: 142.85 | E514: 6041137 | F514: 6041137
A515: 5012994 - SD EXTRA EBONY 2.5L | B515: 10 | C515: 142.16 | E515: 5012994 | F515: 5012994
A516: 6042110 - DS PRESTIGE CAGE FRAME 9IN | B516: 0 | C516: 141.9 | E516: 6042110 | F516: 6042110
A517: 5028579 - SD EXTRA NATURAL 2.5L | B517: 10 | C517: 140.47 | E517: 5028579 | F517: 5028579
A518: 5027813 - MC GLOSS BLACK 5L | B518: 40 | C518: 140.11 | E518: 5027813 | F518: 5027813
A519: 6041627 - DS PRODEC LONG LIFE MASK TAPE 50MM 50M | B519: 0 | C519: 139.8 | E519: 6041627 | F519: 6041627
A520: 6040923 - DS FROGTAPE M SURF MASK 41.1M 24MM | B520: 0 | C520: 139.17 | E520: 6040923 | F520: 6040923
A521: 5092804 - CT FFLOW QD SATIN BASE OPAL MID 2.5L | B521: 20 | C521: 138.75 | E521: 5092804 | F521: 5092804
A522: 6046274 - DS PRODEC PAINTERS TROUSERS 34IN | B522: 0 | C522: 137.91 | E522: 6046274 | F522: 6046274
A523: 5091198 - ST EGGSHELL X-TRA BASE CRYSTAL DK 2.5L | B523: 7.5 | C523: 137.54 | E523: 5091198 | F523: 5091198
A524: 5027902 - MC UNDERCOAT DEEP GRY 5L | B524: 40 | C524: 136.76 | E524: 5027902 | F524: 5027902
A525: 5091007 - CT EGGSHELL BASE OPAL MID 5L | B525: 25 | C525: 135.88 | E525: 5091007 | F525: 5091007
... A683: 6040200 - WA ERFURT LINING 2000 DOUBLE | B683: 0 | C683: 80.86 | E683: 6040200 | F683: 6040200
A684: 5026922 - CT STRONGHOLD PR UC DARK GREY 2.5L | B684: 15 | C684: 80.64 | E684: 5026922 | F684: 5026922 | G684: 16.67 | H684: 4.8374325
A685: 5027121 - CT UNDERCOAT DARK GREY 2.5L | B685: 22.5 | C685: 80.41 | E685: 5027121 | F685: 5027121
A686: 5040681 - CT MATT EMULSION MAGNOLIA 6L | B686: 12 | C686: 80.41 | E686: 5040681 | F686: 5040681
A687: 6047222 - DS FARR & BALL MODERN EMULSION 2.5L | B687: 0 | C687: 79.86 | E687: 6047222 | F687: 6047222
A688: 6056052 - DS GYPROC JOINT TAPE 153M | B688: 0 | C688: 79.36 | E688: 6056052 | F688: 6056052
A689: 6047049 - DS BOLLOM FGUARD UL MAT WHITE BASE 5L | B689: 0 | C689: 79.34 | E689: 6047049 | F689: 6047049
A690: 5028845 - SD SUPERDEC BASE WHITE W0 2.5L | B690: 5 | C690: 79.02 | E690: 5028845 | F690: 5028845
A691: 5091144 - MC VINYL MATT EMUL BASE MC1 10L | B691: 40 | C691: 78.76 | E691: 5091144 | F691: 5091144
A692: 6041625 - DS PRODEC PRE EDGE MASK 48MM 50M | B692: 0 | C692: 78.39 | E692: 6041625 | F692: 6041625
A693: 5028739 - SD PV67 GLOSS SET 5L | B693: 5 | C693: 78.08 | E693: 5028739 | F693: 5028739
A694: 6046066 - DS PRESTIGE BUCKET 25L | B694: 0 | C694: 77.81 | E694: 6046066 | F694: 6046066
A695: 6047194 - DS PURDY POWERLOCK EXTENSION POLE 4-8FT | B695: 0 | C695: 77.7 | E695: 6047194 | F695: 6047194
A696: 6046869 - DS BEDEC MSP GLOSS BLACK 750ML | B696: 0 | C696: 77.52 | E696: 6046869 | F696: 6046869
...

Sheet Sheet5
A1: Cust_No. | B1: SAP_Number | C1: Matl_Desc. | D1: Price | E1: Desc. | F1: Size | G1: Unit | H1: Date | I1: EAN-code | J1: Currency
A2: 12973 | B2: 5091367 | C2: SD BEAUTIFLEX WHITE 2.5L | D2: 38.64 | E2: SAD Beautiflex White | F2: 1 | G2: PC | H2: 45505 | I2: 5010131557972 | J2: GBP
A3: 12973 | B3: 5091369 | C3: SD BEAUTIFLEX BLACK 2.5L | D3: 38.64 | E3: SAD Beautiflex Colour | F3: 1 | G3: PC | H3: 45505 | I3: 5010131557996 | J3: GBP
A4: 12973 | B4: 5091371 | C4: SD BEAUTIFLEX HICKORY 2.5L | D4: 37.52 | E4: SAD Beautiflex Colour | F4: 1 | G4: PC | H4: 45505 | I4: 5010131558016 | J4: GBP
A5: 12973 | B5: 5091374 | C5: SD BEAUTIFLEX BASE WHITE W0 1L | D5: 17.39 | E5: SAD Beautiflex Base White | F5: 1 | G5: PC | H5: 45505 | I5: 5010131558047 | J5: GBP
A6: 12973 | B6: 5091375 | C6: SD BEAUTIFLEX BASE WHITE W0 2.5L | D6: 38.64 | E6: SAD Beautiflex Base White | F6: 1 | G6: PC | H6: 45505 | I6: 5010131558054 | J6: GBP
A7: 12973 | B7: 5091372 | C7: SD BEAUTIFLEX BASE CLEAR 065 1L | D7: 17.39 | E7: SAD Beautiflex Base Clear | F7: 1 | G7: PC | H7: 45505 | I7: 5010131558023 | J7: GBP
A8: 12973 | B8: 5091373 | C8: SD BEAUTIFLEX BASE CLEAR 065 2.5L | D8: 38.64 | E8: SAD Beautiflex Base Clear | F8: 1 | G8: PC | H8: 45505 | I8: 5010131558030 | J8: GBP
A9: 12973 | B9: 5028473 | C9: SD CLASSIC REDWOOD 1L | D9: 15.46 | E9: SAD Classic Standard COL | F9: 1 | G9: PC | H9: 45505 | I9: 5721147600711 | J9: GBP
A10: 12973 | B10: 5028475 | C10: SD CLASSIC DK PALSNDR 1L | D10: 15.46 | E10: SAD Classic Standard COL | F10: 1 | G10: PC | H10: 45505 | I10: 5721147660913 | J10: GBP
A11: 12973 | B11: 5028476 | C11: SD CLASSIC DK PALSNDR 2.5L | D11: 36.12 | E11: SAD Classic Standard COL | F11: 1 | G11: PC | H11: 45505 | I11: 5721147660920 | J11: GBP
A12: 12973 | B12: 5028477 | C12: SD CLASSIC DK PALSNDR 5L | D12: 67.1 | E12: SAD Classic Standard COL | F12: 1 | G12: PC | H12: 45505 | I12: 5721147660937 | J12: GBP
A13: 12973 | B13: 5028479 | C13: SD CLASSIC BURMA TEAK 1L | D13: 15.46 | E13: SAD Classic Standard COL | F13: 1 | G13: PC | H13: 45505 | I13: 5721147602111 | J13: GBP
... A185: 12973 | B185: 5093217 | C185: SD SHED AND FENCE PROT WDLND WLK 5L | D185: 18.11 | E185: SAD Shed & Fence Prot COL | F185: 1 | G185: PC | H185: 45505 | I185: 5010131573842 | J185: GBP
A186: 6048267 - DE WHITE SPIRIT 2L | B186: 0 | C186: 839.5 | E186: 6048267 | F186: 6048267 | G186: 3 | H186: 279.83333
A187: 6041190 - DS COOVAR LO LINE MARK YELLOW 5L | B187: 0 | C187: 832.86 | E187: 6041190 | F187: 6041190 | G187: 74.66 | H187: 11.155371
A188: 5091090 - CT UNDERCOAT BASE OPAL MID 5L | B188: 530 | C188: 1562.36 | E188: 5091090 | F188: 5091090 | G188: 16.32 | H188: 95.732843
A189: 6055316 - CT FUNGICIDAL SOLUTION CLEAR 5L | B189: 190 | C189: 826.24 | E189: 6055316 | F189: 6055316 | G189: 24.23 | H189: 34.099876
A190: 5091093 - CT UNDERCOAT BASE PLATNUM LT 5L | B190: 170 | C190: 512.28 | E190: 5091093 | F190: 5091093 | G190: 16.32 | H190: 31.389706
A191: 6054132 - WA GALERIE PALAZZO | B191: 0 | C191: 823.4 | E191: 6054132 | F191: 6054132 | G191: 35.8 | H191: 23
A192: 6042316 - DS BLACKROCK PAINTERS L/W GRIPPER GLOVES | B192: 0 | C192: 806.65 | E192: 6042316 | F192: 6042316 | G192: 3.25 | H192: 248.2
A193: 6055427 - DE PROFESSIONAL LONG PILE ROLLER 4IN | B193: 0 | C193: 800.49 | E193: 6055427 | F193: 6055427 | G193: 0.38 | H193: 2106.5526
A194: 6041876 - DS RUSTOLEUM COMBICOL MATT BLACK 2.5L | B194: 0 | C194: 796 | E194: 6041876 | F194: 6041876 | G194: 47.2 | H194: 16.864407
A195: 5038010 - SD POLY EXT DUR VARNISH CLEAR GLOS 2.5L | B195: 70 | C195: 792.58 | E195: 5038010 | F195: 5038010 | G195: 30.58 | H195: 25.918247
A196: 6055201 - DE ESS PAINT BRUSH 2IN(12) EACH | B196: 0 | C196: 778.18 | E196: 6055201 | F196: 6055201 | G196: 1.38 | H196: 563.89855
A197: 6060534 - DS TOUPRET EXT MASONRY POWDER FILL 15K | B197: 0 | C197: 776.96 | E197: 6060534 | F197: 6060534 | G197: 61.67 | H197: 12.59867
... A224: 6055436 - DE ULTIMATE MICROFIBRE MEDUIM ROLL 4IN | B224: 0 | C224: 679.07 | E224: 6055436 | F224: 6055436 | G224: 0.39 | H224: 1741.2051
A225: 5091122 - MC MARBLETEX SMTH BASE MC2 5L | B225: 85 | C225: 288.01 | E225: 5091122 | F225: 5091122 | G225: 0 | H225: #DIV/0!
A226: 5091131 - MC POWERKOTE BASE MC1 5L | B226: 750 | C226: 2604.93 | E226: 5091131 | F226: 5091131 | G226: 18.7 | H226: 139.30107
A227: 5040770 - ST W/B STAB SOLUTION CLEAR 5L | B227: 80 | C227: 663.88 | E227: 5040770 | F227: 5040770 | G227: 44.38 | H227: 14.958991
